Workbook

Sheet Contents
A1: S&OP demand and material review - data and calculations
A3: SYNTHETIC DATA. Region names and the North America revenue weighting come from public filings and public role titles. Every order, date and dollar figure is generated. This demonstrates a method and represents no company's actual business.
A7: Tab | B7: What is on it | C7: Type
A8: Raw Orders | B8: The order book as an ERP would extract it. Values only, one row per project. | C8: source
A9: Engineered Orders | B9: Fields derived per order: material committed, slip, status, material at risk. | C9: formulas
A10: Monthly by Region | B10: Bookings, conversions, backlog and book-to-bill by region and month. | C10: formulas
A11: Slip by Market | B11: Schedule slip distribution per market, P10 / P50 / P90. | C11: formulas
A12: Region vs Market | B12: Each market's P90 against its region's blended P90. | C12: formulas
A13: Lookback | B13: Expected against actual conversion by region and month, with cumulative bias. | C13: formulas
A14: Commitment | B14: Material committed against backlog at a range of realization assumptions. | C14: formulas
A15: MC Forward | B15: Forward requirement by month. Simulated P10/P50/P90; spread and firm share are formulas. | C15: mixed
A16: MC Coverage | B16: Walk-forward test. How often the stated interval contained the outcome, by months ahead. | C16: mixed
A19: On the two model-output tabs
A20: Excel reproduces every aggregate in this workbook, including the whole coverage test. The one thing it cannot reasonably do is run 4,000 simulations across the order book, so the P10/P50/P90 columns on the two MC tabs are simulated values. Everything derived from them is a formula. The scripts are in the same repository.
A24: Material rate used throughout (from the case study) | C24: 0.5

Sheet Raw Orders
A1: Raw order book
A4: order_id | B4: region | C4: market | D4: booked_month | E4: mw | F4: order_value | G4: promised_months | H4: expected_conversion | I4: actual_conversion | J4: cancelled | K4: slip_months
A5: NX-00001 | B5: North America | C5: US / Canada | D5: 45292 | E5: 31.5 | F5: 2614500 | G5: 16 | H5: 45778 | I5: 45809 | J5: FALSE | K5: 0.9
A6: NX-00002 | B6: North America | C6: US / Canada | D6: 45292 | E6: 24.9 | F6: 2066700 | G6: 15 | H6: 45748 | I6: 45748 | J6: FALSE | K6: 0.01
A7: NX-00003 | B7: North America | C7: US / Canada | D7: 45292 | E7: 10.8 | F7: 896400 | G7: 5 | H7: 45444 | I7: 45536 | J7: FALSE | K7: 2.58
A8: NX-00004 | B8: North America | C8: US / Canada | D8: 45292 | E8: 6 | F8: 498000 | G8: 5 | H8: 45444 | I8: 45444 | J8: FALSE | K8: 0
A9: NX-00005 | B9: North America | C9: US / Canada | D9: 45292 | E9: 4.2 | F9: 348600 | G9: 11 | H9: 45627 | I9: 45627 | J9: FALSE | K9: 0.11
A10: NX-00006 | B10: North America | C10: US / Canada | D10: 45292 | E10: 11.9 | F10: 987700 | G10: 8 | H10: 45536 | I10: 45536 | J10: FALSE | K10: 0.03
A11: NX-00007 | B11: North America | C11: US / Canada | D11: 45292 | E11: 15.3 | F11: 1269900 | G11: 11 | H11: 45627 | I11: 45627 | J11: FALSE | K11: 0.3
A12: NX-00008 | B12: North America | C12: US / Canada | D12: 45292 | E12: 12.5 | F12: 1037500 | G12: 5 | H12: 45444 | I12: 45536 | J12: FALSE | K12: 3.42
A13: NX-00009 | B13: North America | C13: US / Canada | D13: 45292 | E13: 21.5 | F13: 1784500 | G13: 5 | H13: 45444 | I13: 45444 | J13: FALSE | K13: 0.08
A14: NX-00010 | B14: North America | C14: US / Canada | D14: 45292 | E14: 17.5 | F14: 1452500 | G14: 12 | H14: 45658 | I14: 45689 | J14: FALSE | K14: 1.12
A15: NX-00011 | B15: North America | C15: US / Canada | D15: 45292 | E15: 14.4 | F15: 1195200 | G15: 10 | H15: 45597 | I15: 45627 | J15: FALSE | K15: 0.67
A16: NX-00012 | B16: North America | C16: US / Canada | D16: 45292 | E16: 30.7 | F16: 2548100 | G16: 5 | H16: 45444 | I16: 45444 | J16: FALSE | K16: 0
... A22: NX-00018 | B22: EMEA | C22: MENA | D22: 45292 | E22: 3.6 | F22: 291600 | G22: 6 | H22: 45474 | I22: 45566 | J22: FALSE | K22: 2.76
A23: NX-00019 | B23: EMEA | C23: MENA | D23: 45292 | E23: 36.2 | F23: 2932200 | G23: 12 | H23: 45658 | J23: TRUE | K23: 0.09
A24: NX-00020 | B24: EMEA | C24: MENA | D24: 45292 | E24: 34.1 | F24: 2762100 | G24: 9 | H24: 45566 | I24: 45566 | J24: FALSE | K24: 0.18
A25: NX-00021 | B25: APAC | C25: India | D25: 45292 | E25: 18.9 | F25: 1341900 | G25: 5 | H25: 45444 | I25: 46054 | J25: FALSE | K25: 20.04
A26: NX-00022 | B26: APAC | C26: India | D26: 45292 | E26: 4.9 | F26: 347900 | G26: 7 | H26: 45505 | I26: 45566 | J26: FALSE | K26: 1.76
A27: NX-00023 | B27: APAC | C27: India | D27: 45292 | E27: 19.3 | F27: 1370300 | G27: 12 | H27: 45658 | I27: 46204 | J27: FALSE | K27: 18.15
A28: NX-00024 | B28: APAC | C28: Australia/SEA | D28: 45292 | E28: 7.2 | F28: 604800 | G28: 6 | H28: 45474 | I28: 45474 | J28: FALSE | K28: 0.01
A29: NX-00025 | B29: North America | C29: US / Canada | D29: 45323 | E29: 12.3 | F29: 1020900 | G29: 5 | H29: 45474 | I29: 45505 | J29: FALSE | K29: 0.64
A30: NX-00026 | B30: North America | C30: US / Canada | D30: 45323 | E30: 12.2 | F30: 1012600 | G30: 9 | H30: 45597 | I30: 45627 | J30: FALSE | K30: 1.07
A31: NX-00027 | B31: North America | C31: US / Canada | D31: 45323 | E31: 10.8 | F31: 896400 | G31: 6 | H31: 45505 | I31: 45505 | J31: FALSE | K31: 0.16
A32: NX-00028 | B32: North America | C32: US / Canada | D32: 45323 | E32: 16.5 | F32: 1369500 | G32: 5 | H32: 45474 | I32: 45474 | J32: FALSE | K32: 0.02
A33: NX-00029 | B33: North America | C33: US / Canada | D33: 45323 | E33: 7.2 | F33: 597600 | G33: 5 | H33: 45474 | I33: 45474 | J33: FALSE | K33: 0.08
A34: NX-00030 | B34: North America | C34: US / Canada | D34: 45323 | E34: 5 | F34: 415000 | G34: 5 | H34: 45474 | I34: 45474 | J34: FALSE | K34: 0
A35: NX-00031 | B35: North America | C35: US / Canada | D35: 45323 | E35: 20.5 | F35: 1701500 | G35: 6 | H35: 45505 | I35: 45505 | J35: FALSE | K35: 0.06
... A60: NX-00056 | B60: APAC | C60: India | D60: 45323 | E60: 10.7 | F60: 759700 | G60: 12 | H60: 45689 | I60: 45689 | J60: FALSE | K60: 0.05
A61: NX-00057 | B61: APAC | C61: India | D61: 45323 | E61: 21.3 | F61: 1512300 | G61: 8 | H61: 45566 | J61: TRUE | K61: 20.23
A62: NX-00058 | B62: LATAM | C62: LATAM | D62: 45323 | E62: 6.4 | F62: 505600 | G62: 5 | H62: 45474 | I62: 45748 | J62: FALSE | K62: 8.66
A63: NX-00059 | B63: LATAM | C63: LATAM | D63: 45323 | E63: 11.8 | F63: 932200 | G63: 6 | H63: 45505 | I63: 45627 | J63: FALSE | K63: 3.54
A64: NX-00060 | B64: North America | C64: US / Canada | D64: 45352 | E64: 7.2 | F64: 597600 | G64: 8 | H64: 45597 | I64: 45627 | J64: FALSE | K64: 0.5
A65: NX-00061 | B65: North America | C65: US / Canada | D65: 45352 | E65: 18.9 | F65: 1568700 | G65: 6 | H65: 45536 | I65: 45536 | J65: FALSE | K65: 0
A66: NX-00062 | B66: North America | C66: US / Canada | D66: 45352 | E66: 32.5 | F66: 2697500 | G66: 6 | H66: 45536 | I66: 45566 | J66: FALSE | K66: 0.7
A67: NX-00063 | B67: North America | C67: US / Canada | D67: 45352 | E67: 10.2 | F67: 846600 | G67: 12 | H67: 45717 | I67: 45748 | J67: FALSE | K67: 1.45
A68: NX-00064 | B68: North America | C68: US / Canada | D68: 45352 | E68: 82.5 | F68: 6847500 | G68: 8 | H68: 45597 | I68: 45597 | J68: FALSE | K68: 0.03
A69: NX-00065 | B69: North America | C69: US / Canada | D69: 45352 | E69: 29.9 | F69: 2481700 | G69: 6 | H69: 45536 | I69: 45536 | J69: FALSE | K69: 0.48
A70: NX-00066 | B70: North America | C70: US / Canada | D70: 45352 | E70: 5.6 | F70: 464800 | G70: 12 | H70: 45717 | I70: 45748 | J70: FALSE | K70: 0.94
A71: NX-00067 | B71: North America | C71: US / Canada | D71: 45352 | E71: 11.3 | F71: 937900 | G71: 5 | H71: 45505 | I71: 45536 | J71: FALSE | K71: 1.46
...

Sheet Engineered Orders
A1: Engineered fields
F3: =order_value x material rate | J3: =whole months between expected and actual, a check on the supplied slip
A4: order_id | B4: region | C4: market | D4: mw | E4: order_value | F4: material_committed | G4: expected_conversion | H4: actual_conversion | I4: slip_months | J4: slip_check_from_dates | K4: status | L4: material_at_risk
A5: ='Raw Orders'!A5 | B5: ='Raw Orders'!B5 | C5: ='Raw Orders'!C5 | D5: ='Raw Orders'!E5 | E5: ='Raw Orders'!F5 | F5: ='Raw Orders'!F5*0.5 | G5: ='Raw Orders'!H5 | H5: ='Raw Orders'!I5 | I5: ='Raw Orders'!K5 | J5: =IF('Raw Orders'!J5,"",(YEAR('Raw Orders'!I5)-YEAR('Raw Orders'!H5))*12+MONTH('Raw Orders'!I5)-MONTH('Raw Orders'!H5)) | K5: =IF('Raw Orders'!J5,"Cancelled",IF('Raw Orders'!K5>=2,"Slipped","On plan")) | L5: =IF(K5="On plan",0,F5)
A6: ='Raw Orders'!A6 | B6: ='Raw Orders'!B6 | C6: ='Raw Orders'!C6 | D6: ='Raw Orders'!E6 | E6: ='Raw Orders'!F6 | F6: ='Raw Orders'!F6*0.5 | G6: ='Raw Orders'!H6 | H6: ='Raw Orders'!I6 | I6: ='Raw Orders'!K6 | J6: =IF('Raw Orders'!J6,"",(YEAR('Raw Orders'!I6)-YEAR('Raw Orders'!H6))*12+MONTH('Raw Orders'!I6)-MONTH('Raw Orders'!H6)) | K6: =IF('Raw Orders'!J6,"Cancelled",IF('Raw Orders'!K6>=2,"Slipped","On plan")) | L6: =IF(K6="On plan",0,F6)
A7: ='Raw Orders'!A7 | B7: ='Raw Orders'!B7 | C7: ='Raw Orders'!C7 | D7: ='Raw Orders'!E7 | E7: ='Raw Orders'!F7 | F7: ='Raw Orders'!F7*0.5 | G7: ='Raw Orders'!H7 | H7: ='Raw Orders'!I7 | I7: ='Raw Orders'!K7 | J7: =IF('Raw Orders'!J7,"",(YEAR('Raw Orders'!I7)-YEAR('Raw Orders'!H7))*12+MONTH('Raw Orders'!I7)-MONTH('Raw Orders'!H7)) | K7: =IF('Raw Orders'!J7,"Cancelled",IF('Raw Orders'!K7>=2,"Slipped","On plan")) | L7: =IF(K7="On plan",0,F7)
A8: ='Raw Orders'!A8 | B8: ='Raw Orders'!B8 | C8: ='Raw Orders'!C8 | D8: ='Raw Orders'!E8 | E8: ='Raw Orders'!F8 | F8: ='Raw Orders'!F8*0.5 | G8: ='Raw Orders'!H8 | H8: ='Raw Orders'!I8 | I8: ='Raw Orders'!K8 | J8: =IF('Raw Orders'!J8,"",(YEAR('Raw Orders'!I8)-YEAR('Raw Orders'!H8))*12+MONTH('Raw Orders'!I8)-MONTH('Raw Orders'!H8)) | K8: =IF('Raw Orders'!J8,"Cancelled",IF('Raw Orders'!K8>=2,"Slipped","On plan")) | L8: =IF(K8="On plan",0,F8)
A9: ='Raw Orders'!A9 | B9: ='Raw Orders'!B9 | C9: ='Raw Orders'!C9 | D9: ='Raw Orders'!E9 | E9: ='Raw Orders'!F9 | F9: ='Raw Orders'!F9*0.5 | G9: ='Raw Orders'!H9 | H9: ='Raw Orders'!I9 | I9: ='Raw Orders'!K9 | J9: =IF('Raw Orders'!J9,"",(YEAR('Raw Orders'!I9)-YEAR('Raw Orders'!H9))*12+MONTH('Raw Orders'!I9)-MONTH('Raw Orders'!H9)) | K9: =IF('Raw Orders'!J9,"Cancelled",IF('Raw Orders'!K9>=2,"Slipped","On plan")) | L9: =IF(K9="On plan",0,F9)
A10: ='Raw Orders'!A10 | B10: ='Raw Orders'!B10 | C10: ='Raw Orders'!C10 | D10: ='Raw Orders'!E10 | E10: ='Raw Orders'!F10 | F10: ='Raw Orders'!F10*0.5 | G10: ='Raw Orders'!H10 | H10: ='Raw Orders'!I10 | I10: ='Raw Orders'!K10 | J10: =IF('Raw Orders'!J10,"",(YEAR('Raw Orders'!I10)-YEAR('Raw Orders'!H10))*12+MONTH('Raw Orders'!I10)-MONTH('Raw Orders'!H10)) | K10: =IF('Raw Orders'!J10,"Cancelled",IF('Raw Orders'!K10>=2,"Slipped","On plan")) | L10: =IF(K10="On plan",0,F10)
A11: ='Raw Orders'!A11 | B11: ='Raw Orders'!B11 | C11: ='Raw Orders'!C11 | D11: ='Raw Orders'!E11 | E11: ='Raw Orders'!F11 | F11: ='Raw Orders'!F11*0.5 | G11: ='Raw Orders'!H11 | H11: ='Raw Orders'!I11 | I11: ='Raw Orders'!K11 | J11: =IF('Raw Orders'!J11,"",(YEAR('Raw Orders'!I11)-YEAR('Raw Orders'!H11))*12+MONTH('Raw Orders'!I11)-MONTH('Raw Orders'!H11)) | K11: =IF('Raw Orders'!J11,"Cancelled",IF('Raw Orders'!K11>=2,"Slipped","On plan")) | L11: =IF(K11="On plan",0,F11)
A12: ='Raw Orders'!A12 | B12: ='Raw Orders'!B12 | C12: ='Raw Orders'!C12 | D12: ='Raw Orders'!E12 | E12: ='Raw Orders'!F12 | F12: ='Raw Orders'!F12*0.5 | G12: ='Raw Orders'!H12 | H12: ='Raw Orders'!I12 | I12: ='Raw Orders'!K12 | J12: =IF('Raw Orders'!J12,"",(YEAR('Raw Orders'!I12)-YEAR('Raw Orders'!H12))*12+MONTH('Raw Orders'!I12)-MONTH('Raw Orders'!H12)) | K12: =IF('Raw Orders'!J12,"Cancelled",IF('Raw Orders'!K12>=2,"Slipped","On plan")) | L12: =IF(K12="On plan",0,F12)
A13: ='Raw Orders'!A13 | B13: ='Raw Orders'!B13 | C13: ='Raw Orders'!C13 | D13: ='Raw Orders'!E13 | E13: ='Raw Orders'!F13 | F13: ='Raw Orders'!F13*0.5 | G13: ='Raw Orders'!H13 | H13: ='Raw Orders'!I13 | I13: ='Raw Orders'!K13 | J13: =IF('Raw Orders'!J13,"",(YEAR('Raw Orders'!I13)-YEAR('Raw Orders'!H13))*12+MONTH('Raw Orders'!I13)-MONTH('Raw Orders'!H13)) | K13: =IF('Raw Orders'!J13,"Cancelled",IF('Raw Orders'!K13>=2,"Slipped","On plan")) | L13: =IF(K13="On plan",0,F13)
A14: ='Raw Orders'!A14 | B14: ='Raw Orders'!B14 | C14: ='Raw Orders'!C14 | D14: ='Raw Orders'!E14 | E14: ='Raw Orders'!F14 | F14: ='Raw Orders'!F14*0.5 | G14: ='Raw Orders'!H14 | H14: ='Raw Orders'!I14 | I14: ='Raw Orders'!K14 | J14: =IF('Raw Orders'!J14,"",(YEAR('Raw Orders'!I14)-YEAR('Raw Orders'!H14))*12+MONTH('Raw Orders'!I14)-MONTH('Raw Orders'!H14)) | K14: =IF('Raw Orders'!J14,"Cancelled",IF('Raw Orders'!K14>=2,"Slipped","On plan")) | L14: =IF(K14="On plan",0,F14)
A15: ='Raw Orders'!A15 | B15: ='Raw Orders'!B15 | C15: ='Raw Orders'!C15 | D15: ='Raw Orders'!E15 | E15: ='Raw Orders'!F15 | F15: ='Raw Orders'!F15*0.5 | G15: ='Raw Orders'!H15 | H15: ='Raw Orders'!I15 | I15: ='Raw Orders'!K15 | J15: =IF('Raw Orders'!J15,"",(YEAR('Raw Orders'!I15)-YEAR('Raw Orders'!H15))*12+MONTH('Raw Orders'!I15)-MONTH('Raw Orders'!H15)) | K15: =IF('Raw Orders'!J15,"Cancelled",IF('Raw Orders'!K15>=2,"Slipped","On plan")) | L15: =IF(K15="On plan",0,F15)
A16: ='Raw Orders'!A16 | B16: ='Raw Orders'!B16 | C16: ='Raw Orders'!C16 | D16: ='Raw Orders'!E16 | E16: ='Raw Orders'!F16 | F16: ='Raw Orders'!F16*0.5 | G16: ='Raw Orders'!H16 | H16: ='Raw Orders'!I16 | I16: ='Raw Orders'!K16 | J16: =IF('Raw Orders'!J16,"",(YEAR('Raw Orders'!I16)-YEAR('Raw Orders'!H16))*12+MONTH('Raw Orders'!I16)-MONTH('Raw Orders'!H16)) | K16: =IF('Raw Orders'!J16,"Cancelled",IF('Raw Orders'!K16>=2,"Slipped","On plan")) | L16: =IF(K16="On plan",0,F16)
... A852: ='Raw Orders'!A852 | B852: ='Raw Orders'!B852 | C852: ='Raw Orders'!C852 | D852: ='Raw Orders'!E852 | E852: ='Raw Orders'!F852 | F852: ='Raw Orders'!F852*0.5 | G852: ='Raw Orders'!H852 | H852: ='Raw Orders'!I852 | I852: ='Raw Orders'!K852 | J852: =IF('Raw Orders'!J852,"",(YEAR('Raw Orders'!I852)-YEAR('Raw Orders'!H852))*12+MONTH('Raw Orders'!I852)-MONTH('Raw Orders'!H852)) | K852: =IF('Raw Orders'!J852,"Cancelled",IF('Raw Orders'!K852>=2,"Slipped","On plan")) | L852: =IF(K852="On plan",0,F852)

Sheet Monthly by Region
A1: Monthly aggregates by region
A4: region | B4: month | C4: orders booked | D4: MW booked | E4: value booked ($) | F4: value converted ($) | G4: backlog ($) | H4: book-to-bill | I4: material vs backlog ($)
A5: North America | B5: 45292 | C5: =COUNTIFS('Raw Orders'!$B$5:$B$852,$A5,'Raw Orders'!$D$5:$D$852,$B5) | D5: =SUMIFS('Raw Orders'!$E$5:$E$852,'Raw Orders'!$B$5:$B$852,$A5,'Raw Orders'!$D$5:$D$852,$B5) | E5: =SUMIFS('Raw Orders'!$F$5:$F$852,'Raw Orders'!$B$5:$B$852,$A5,'Raw Orders'!$D$5:$D$852,$B5) | F5: =SUMIFS('Raw Orders'!$F$5:$F$852,'Raw Orders'!$B$5:$B$852,$A5,'Raw Orders'!$I$5:$I$852,$B5,'Raw Orders'!$J$5:$J$852,FALSE) | G5: =SUMIFS('Raw Orders'!$F$5:$F$852,'Raw Orders'!$B$5:$B$852,$A5,'Raw Orders'!$D$5:$D$852,"<="&$B5,'Raw Orders'!$J$5:$J$852,FALSE)-SUMIFS('Raw Orders'!$F$5:$F$852,'Raw Orders'!$B$5:$B$852,$A5,'Raw Orders'!$I$5:$I$852,"<="&$B5,'Raw Orders'!$J$5:$J$852,FALSE) | H5: =IF(F5=0,"",E5/F5) | I5: =G5*0.5
A6: North America | B6: 45323 | C6: =COUNTIFS('Raw Orders'!$B$5:$B$852,$A6,'Raw Orders'!$D$5:$D$852,$B6) | D6: =SUMIFS('Raw Orders'!$E$5:$E$852,'Raw Orders'!$B$5:$B$852,$A6,'Raw Orders'!$D$5:$D$852,$B6) | E6: =SUMIFS('Raw Orders'!$F$5:$F$852,'Raw Orders'!$B$5:$B$852,$A6,'Raw Orders'!$D$5:$D$852,$B6) | F6: =SUMIFS('Raw Orders'!$F$5:$F$852,'Raw Orders'!$B$5:$B$852,$A6,'Raw Orders'!$I$5:$I$852,$B6,'Raw Orders'!$J$5:$J$852,FALSE) | G6: =SUMIFS('Raw Orders'!$F$5:$F$852,'Raw Orders'!$B$5:$B$852,$A6,'Raw Orders'!$D$5:$D$852,"<="&$B6,'Raw Orders'!$J$5:$J$852,FALSE)-SUMIFS('Raw Orders'!$F$5:$F$852,'Raw Orders'!$B$5:$B$852,$A6,'Raw Orders'!$I$5:$I$852,"<="&$B6,'Raw Orders'!$J$5:$J$852,FALSE) | H6: =IF(F6=0,"",E6/F6) | I6: =G6*0.5
A7: North America | B7: 45352 | C7: =COUNTIFS('Raw Orders'!$B$5:$B$852,$A7,'Raw Orders'!$D$5:$D$852,$B7) | D7: =SUMIFS('Raw Orders'!$E$5:$E$852,'Raw Orders'!$B$5:$B$852,$A7,'Raw Orders'!$D$5:$D$852,$B7) | E7: =SUMIFS('Raw Orders'!$F$5:$F$852,'Raw Orders'!$B$5:$B$852,$A7,'Raw Orders'!$D$5:$D$852,$B7) | F7: =SUMIFS('Raw Orders'!$F$5:$F$852,'Raw Orders'!$B$5:$B$852,$A7,'Raw Orders'!$I$5:$I$852,$B7,'Raw Orders'!$J$5:$J$852,FALSE) | G7: =SUMIFS('Raw Orders'!$F$5:$F$852,'Raw Orders'!$B$5:$B$852,$A7,'Raw Orders'!$D$5:$D$852,"<="&$B7,'Raw Orders'!$J$5:$J$852,FALSE)-SUMIFS('Raw Orders'!$F$5:$F$852,'Raw Orders'!$B$5:$B$852,$A7,'Raw Orders'!$I$5:$I$852,"<="&$B7,'Raw Orders'!$J$5:$J$852,FALSE) | H7: =IF(F7=0,"",E7/F7) | I7: =G7*0.5
A8: North America | B8: 45383 | C8: =COUNTIFS('Raw Orders'!$B$5:$B$852,$A8,'Raw Orders'!$D$5:$D$852,$B8) | D8: =SUMIFS('Raw Orders'!$E$5:$E$852,'Raw Orders'!$B$5:$B$852,$A8,'Raw Orders'!$D$5:$D$852,$B8) | E8: =SUMIFS('Raw Orders'!$F$5:$F$852,'Raw Orders'!$B$5:$B$852,$A8,'Raw Orders'!$D$5:$D$852,$B8) | F8: =SUMIFS('Raw Orders'!$F$5:$F$852,'Raw Orders'!$B$5:$B$852,$A8,'Raw Orders'!$I$5:$I$852,$B8,'Raw Orders'!$J$5:$J$852,FALSE) | G8: =SUMIFS('Raw Orders'!$F$5:$F$852,'Raw Orders'!$B$5:$B$852,$A8,'Raw Orders'!$D$5:$D$852,"<="&$B8,'Raw Orders'!$J$5:$J$852,FALSE)-SUMIFS('Raw Orders'!$F$5:$F$852,'Raw Orders'!$B$5:$B$852,$A8,'Raw Orders'!$I$5:$I$852,"<="&$B8,'Raw Orders'!$J$5:$J$852,FALSE) | H8: =IF(F8=0,"",E8/F8) | I8: =G8*0.5
A9: North America | B9: 45413 | C9: =COUNTIFS('Raw Orders'!$B$5:$B$852,$A9,'Raw Orders'!$D$5:$D$852,$B9) | D9: =SUMIFS('Raw Orders'!$E$5:$E$852,'Raw Orders'!$B$5:$B$852,$A9,'Raw Orders'!$D$5:$D$852,$B9) | E9: =SUMIFS('Raw Orders'!$F$5:$F$852,'Raw Orders'!$B$5:$B$852,$A9,'Raw Orders'!$D$5:$D$852,$B9) | F9: =SUMIFS('Raw Orders'!$F$5:$F$852,'Raw Orders'!$B$5:$B$852,$A9,'Raw Orders'!$I$5:$I$852,$B9,'Raw Orders'!$J$5:$J$852,FALSE) | G9: =SUMIFS('Raw Orders'!$F$5:$F$852,'Raw Orders'!$B$5:$B$852,$A9,'Raw Orders'!$D$5:$D$852,"<="&$B9,'Raw Orders'!$J$5:$J$852,FALSE)-SUMIFS('Raw Orders'!$F$5:$F$852,'Raw Orders'!$B$5:$B$852,$A9,'Raw Orders'!$I$5:$I$852,"<="&$B9,'Raw Orders'!$J$5:$J$852,FALSE) | H9: =IF(F9=0,"",E9/F9) | I9: =G9*0.5
A10: North America | B10: 45444 | C10: =COUNTIFS('Raw Orders'!$B$5:$B$852,$A10,'Raw Orders'!$D$5:$D$852,$B10) | D10: =SUMIFS('Raw Orders'!$E$5:$E$852,'Raw Orders'!$B$5:$B$852,$A10,'Raw Orders'!$D$5:$D$852,$B10) | E10: =SUMIFS('Raw Orders'!$F$5:$F$852,'Raw Orders'!$B$5:$B$852,$A10,'Raw Orders'!$D$5:$D$852,$B10) | F10: =SUMIFS('Raw Orders'!$F$5:$F$852,'Raw Orders'!$B$5:$B$852,$A10,'Raw Orders'!$I$5:$I$852,$B10,'Raw Orders'!$J$5:$J$852,FALSE) | G10: =SUMIFS('Raw Orders'!$F$5:$F$852,'Raw Orders'!$B$5:$B$852,$A10,'Raw Orders'!$D$5:$D$852,"<="&$B10,'Raw Orders'!$J$5:$J$852,FALSE)-SUMIFS('Raw Orders'!$F$5:$F$852,'Raw Orders'!$B$5:$B$852,$A10,'Raw Orders'!$I$5:$I$852,"<="&$B10,'Raw Orders'!$J$5:$J$852,FALSE) | H10: =IF(F10=0,"",E10/F10) | I10: =G10*0.5
A11: North America | B11: 45474 | C11: =COUNTIFS('Raw Orders'!$B$5:$B$852,$A11,'Raw Orders'!$D$5:$D$852,$B11) | D11: =SUMIFS('Raw Orders'!$E$5:$E$852,'Raw Orders'!$B$5:$B$852,$A11,'Raw Orders'!$D$5:$D$852,$B11) | E11: =SUMIFS('Raw Orders'!$F$5:$F$852,'Raw Orders'!$B$5:$B$852,$A11,'Raw Orders'!$D$5:$D$852,$B11) | F11: =SUMIFS('Raw Orders'!$F$5:$F$852,'Raw Orders'!$B$5:$B$852,$A11,'Raw Orders'!$I$5:$I$852,$B11,'Raw Orders'!$J$5:$J$852,FALSE) | G11: =SUMIFS('Raw Orders'!$F$5:$F$852,'Raw Orders'!$B$5:$B$852,$A11,'Raw Orders'!$D$5:$D$852,"<="&$B11,'Raw Orders'!$J$5:$J$852,FALSE)-SUMIFS('Raw Orders'!$F$5:$F$852,'Raw Orders'!$B$5:$B$852,$A11,'Raw Orders'!$I$5:$I$852,"<="&$B11,'Raw Orders'!$J$5:$J$852,FALSE) | H11: =IF(F11=0,"",E11/F11) | I11: =G11*0.5
A12: North America | B12: 45505 | C12: =COUNTIFS('Raw Orders'!$B$5:$B$852,$A12,'Raw Orders'!$D$5:$D$852,$B12) | D12: =SUMIFS('Raw Orders'!$E$5:$E$852,'Raw Orders'!$B$5:$B$852,$A12,'Raw Orders'!$D$5:$D$852,$B12) | E12: =SUMIFS('Raw Orders'!$F$5:$F$852,'Raw Orders'!$B$5:$B$852,$A12,'Raw Orders'!$D$5:$D$852,$B12) | F12: =SUMIFS('Raw Orders'!$F$5:$F$852,'Raw Orders'!$B$5:$B$852,$A12,'Raw Orders'!$I$5:$I$852,$B12,'Raw Orders'!$J$5:$J$852,FALSE) | G12: =SUMIFS('Raw Orders'!$F$5:$F$852,'Raw Orders'!$B$5:$B$852,$A12,'Raw Orders'!$D$5:$D$852,"<="&$B12,'Raw Orders'!$J$5:$J$852,FALSE)-SUMIFS('Raw Orders'!$F$5:$F$852,'Raw Orders'!$B$5:$B$852,$A12,'Raw Orders'!$I$5:$I$852,"<="&$B12,'Raw Orders'!$J$5:$J$852,FALSE) | H12: =IF(F12=0,"",E12/F12) | I12: =G12*0.5
A13: North America | B13: 45536 | C13: =COUNTIFS('Raw Orders'!$B$5:$B$852,$A13,'Raw Orders'!$D$5:$D$852,$B13) | D13: =SUMIFS('Raw Orders'!$E$5:$E$852,'Raw Orders'!$B$5:$B$852,$A13,'Raw Orders'!$D$5:$D$852,$B13) | E13: =SUMIFS('Raw Orders'!$F$5:$F$852,'Raw Orders'!$B$5:$B$852,$A13,'Raw Orders'!$D$5:$D$852,$B13) | F13: =SUMIFS('Raw Orders'!$F$5:$F$852,'Raw Orders'!$B$5:$B$852,$A13,'Raw Orders'!$I$5:$I$852,$B13,'Raw Orders'!$J$5:$J$852,FALSE) | G13: =SUMIFS('Raw Orders'!$F$5:$F$852,'Raw Orders'!$B$5:$B$852,$A13,'Raw Orders'!$D$5:$D$852,"<="&$B13,'Raw Orders'!$J$5:$J$852,FALSE)-SUMIFS('Raw Orders'!$F$5:$F$852,'Raw Orders'!$B$5:$B$852,$A13,'Raw Orders'!$I$5:$I$852,"<="&$B13,'Raw Orders'!$J$5:$J$852,FALSE) | H13: =IF(F13=0,"",E13/F13) | I13: =G13*0.5
A14: North America | B14: 45566 | C14: =COUNTIFS('Raw Orders'!$B$5:$B$852,$A14,'Raw Orders'!$D$5:$D$852,$B14) | D14: =SUMIFS('Raw Orders'!$E$5:$E$852,'Raw Orders'!$B$5:$B$852,$A14,'Raw Orders'!$D$5:$D$852,$B14) | E14: =SUMIFS('Raw Orders'!$F$5:$F$852,'Raw Orders'!$B$5:$B$852,$A14,'Raw Orders'!$D$5:$D$852,$B14) | F14: =SUMIFS('Raw Orders'!$F$5:$F$852,'Raw Orders'!$B$5:$B$852,$A14,'Raw Orders'!$I$5:$I$852,$B14,'Raw Orders'!$J$5:$J$852,FALSE) | G14: =SUMIFS('Raw Orders'!$F$5:$F$852,'Raw Orders'!$B$5:$B$852,$A14,'Raw Orders'!$D$5:$D$852,"<="&$B14,'Raw Orders'!$J$5:$J$852,FALSE)-SUMIFS('Raw Orders'!$F$5:$F$852,'Raw Orders'!$B$5:$B$852,$A14,'Raw Orders'!$I$5:$I$852,"<="&$B14,'Raw Orders'!$J$5:$J$852,FALSE) | H14: =IF(F14=0,"",E14/F14) | I14: =G14*0.5
A15: North America | B15: 45597 | C15: =COUNTIFS('Raw Orders'!$B$5:$B$852,$A15,'Raw Orders'!$D$5:$D$852,$B15) | D15: =SUMIFS('Raw Orders'!$E$5:$E$852,'Raw Orders'!$B$5:$B$852,$A15,'Raw Orders'!$D$5:$D$852,$B15) | E15: =SUMIFS('Raw Orders'!$F$5:$F$852,'Raw Orders'!$B$5:$B$852,$A15,'Raw Orders'!$D$5:$D$852,$B15) | F15: =SUMIFS('Raw Orders'!$F$5:$F$852,'Raw Orders'!$B$5:$B$852,$A15,'Raw Orders'!$I$5:$I$852,$B15,'Raw Orders'!$J$5:$J$852,FALSE) | G15: =SUMIFS('Raw Orders'!$F$5:$F$852,'Raw Orders'!$B$5:$B$852,$A15,'Raw Orders'!$D$5:$D$852,"<="&$B15,'Raw Orders'!$J$5:$J$852,FALSE)-SUMIFS('Raw Orders'!$F$5:$F$852,'Raw Orders'!$B$5:$B$852,$A15,'Raw Orders'!$I$5:$I$852,"<="&$B15,'Raw Orders'!$J$5:$J$852,FALSE) | H15: =IF(F15=0,"",E15/F15) | I15: =G15*0.5
A16: North America | B16: 45627 | C16: =COUNTIFS('Raw Orders'!$B$5:$B$852,$A16,'Raw Orders'!$D$5:$D$852,$B16) | D16: =SUMIFS('Raw Orders'!$E$5:$E$852,'Raw Orders'!$B$5:$B$852,$A16,'Raw Orders'!$D$5:$D$852,$B16) | E16: =SUMIFS('Raw Orders'!$F$5:$F$852,'Raw Orders'!$B$5:$B$852,$A16,'Raw Orders'!$D$5:$D$852,$B16) | F16: =SUMIFS('Raw Orders'!$F$5:$F$852,'Raw Orders'!$B$5:$B$852,$A16,'Raw Orders'!$I$5:$I$852,$B16,'Raw Orders'!$J$5:$J$852,FALSE) | G16: =SUMIFS('Raw Orders'!$F$5:$F$852,'Raw Orders'!$B$5:$B$852,$A16,'Raw Orders'!$D$5:$D$852,"<="&$B16,'Raw Orders'!$J$5:$J$852,FALSE)-SUMIFS('Raw Orders'!$F$5:$F$852,'Raw Orders'!$B$5:$B$852,$A16,'Raw Orders'!$I$5:$I$852,"<="&$B16,'Raw Orders'!$J$5:$J$852,FALSE) | H16: =IF(F16=0,"",E16/F16) | I16: =G16*0.5
... A100: LATAM | B100: 45992 | C100: =COUNTIFS('Raw Orders'!$B$5:$B$852,$A100,'Raw Orders'!$D$5:$D$852,$B100) | D100: =SUMIFS('Raw Orders'!$E$5:$E$852,'Raw Orders'!$B$5:$B$852,$A100,'Raw Orders'!$D$5:$D$852,$B100) | E100: =SUMIFS('Raw Orders'!$F$5:$F$852,'Raw Orders'!$B$5:$B$852,$A100,'Raw Orders'!$D$5:$D$852,$B100) | F100: =SUMIFS('Raw Orders'!$F$5:$F$852,'Raw Orders'!$B$5:$B$852,$A100,'Raw Orders'!$I$5:$I$852,$B100,'Raw Orders'!$J$5:$J$852,FALSE) | G100: =SUMIFS('Raw Orders'!$F$5:$F$852,'Raw Orders'!$B$5:$B$852,$A100,'Raw Orders'!$D$5:$D$852,"<="&$B100,'Raw Orders'!$J$5:$J$852,FALSE)-SUMIFS('Raw Orders'!$F$5:$F$852,'Raw Orders'!$B$5:$B$852,$A100,'Raw Orders'!$I$5:$I$852,"<="&$B100,'Raw Orders'!$J$5:$J$852,FALSE) | H100: =IF(F100=0,"",E100/F100) | I100: =G100*0.5

Sheet Slip by Market
A1: Schedule slip distribution by market
A4: market | B4: region | C4: orders | D4: P10 | E4: median | F4: P90 | G4: mean
A5: US / Canada | B5: North America | C5: =COUNTIFS('Raw Orders'!$C$5:$C$852,$A5,'Raw Orders'!$J$5:$J$852,FALSE) | D5: {=PERCENTILE(IF(('Raw Orders'!$C$5:$C$852=$A5)*('Raw Orders'!$J$5:$J$852=FALSE),'Raw Orders'!$K$5:$K$852),0.1)} | E5: {=PERCENTILE(IF(('Raw Orders'!$C$5:$C$852=$A5)*('Raw Orders'!$J$5:$J$852=FALSE),'Raw Orders'!$K$5:$K$852),0.5)} | F5: {=PERCENTILE(IF(('Raw Orders'!$C$5:$C$852=$A5)*('Raw Orders'!$J$5:$J$852=FALSE),'Raw Orders'!$K$5:$K$852),0.9)} | G5: =AVERAGEIFS('Raw Orders'!$K$5:$K$852,'Raw Orders'!$C$5:$C$852,$A5,'Raw Orders'!$J$5:$J$852,FALSE)
A6: Europe | B6: EMEA | C6: =COUNTIFS('Raw Orders'!$C$5:$C$852,$A6,'Raw Orders'!$J$5:$J$852,FALSE) | D6: {=PERCENTILE(IF(('Raw Orders'!$C$5:$C$852=$A6)*('Raw Orders'!$J$5:$J$852=FALSE),'Raw Orders'!$K$5:$K$852),0.1)} | E6: {=PERCENTILE(IF(('Raw Orders'!$C$5:$C$852=$A6)*('Raw Orders'!$J$5:$J$852=FALSE),'Raw Orders'!$K$5:$K$852),0.5)} | F6: {=PERCENTILE(IF(('Raw Orders'!$C$5:$C$852=$A6)*('Raw Orders'!$J$5:$J$852=FALSE),'Raw Orders'!$K$5:$K$852),0.9)} | G6: =AVERAGEIFS('Raw Orders'!$K$5:$K$852,'Raw Orders'!$C$5:$C$852,$A6,'Raw Orders'!$J$5:$J$852,FALSE)
A7: MENA | B7: EMEA | C7: =COUNTIFS('Raw Orders'!$C$5:$C$852,$A7,'Raw Orders'!$J$5:$J$852,FALSE) | D7: {=PERCENTILE(IF(('Raw Orders'!$C$5:$C$852=$A7)*('Raw Orders'!$J$5:$J$852=FALSE),'Raw Orders'!$K$5:$K$852),0.1)} | E7: {=PERCENTILE(IF(('Raw Orders'!$C$5:$C$852=$A7)*('Raw Orders'!$J$5:$J$852=FALSE),'Raw Orders'!$K$5:$K$852),0.5)} | F7: {=PERCENTILE(IF(('Raw Orders'!$C$5:$C$852=$A7)*('Raw Orders'!$J$5:$J$852=FALSE),'Raw Orders'!$K$5:$K$852),0.9)} | G7: =AVERAGEIFS('Raw Orders'!$K$5:$K$852,'Raw Orders'!$C$5:$C$852,$A7,'Raw Orders'!$J$5:$J$852,FALSE)
A8: Australia/SEA | B8: APAC | C8: =COUNTIFS('Raw Orders'!$C$5:$C$852,$A8,'Raw Orders'!$J$5:$J$852,FALSE) | D8: {=PERCENTILE(IF(('Raw Orders'!$C$5:$C$852=$A8)*('Raw Orders'!$J$5:$J$852=FALSE),'Raw Orders'!$K$5:$K$852),0.1)} | E8: {=PERCENTILE(IF(('Raw Orders'!$C$5:$C$852=$A8)*('Raw Orders'!$J$5:$J$852=FALSE),'Raw Orders'!$K$5:$K$852),0.5)} | F8: {=PERCENTILE(IF(('Raw Orders'!$C$5:$C$852=$A8)*('Raw Orders'!$J$5:$J$852=FALSE),'Raw Orders'!$K$5:$K$852),0.9)} | G8: =AVERAGEIFS('Raw Orders'!$K$5:$K$852,'Raw Orders'!$C$5:$C$852,$A8,'Raw Orders'!$J$5:$J$852,FALSE)
A9: India | B9: APAC | C9: =COUNTIFS('Raw Orders'!$C$5:$C$852,$A9,'Raw Orders'!$J$5:$J$852,FALSE) | D9: {=PERCENTILE(IF(('Raw Orders'!$C$5:$C$852=$A9)*('Raw Orders'!$J$5:$J$852=FALSE),'Raw Orders'!$K$5:$K$852),0.1)} | E9: {=PERCENTILE(IF(('Raw Orders'!$C$5:$C$852=$A9)*('Raw Orders'!$J$5:$J$852=FALSE),'Raw Orders'!$K$5:$K$852),0.5)} | F9: {=PERCENTILE(IF(('Raw Orders'!$C$5:$C$852=$A9)*('Raw Orders'!$J$5:$J$852=FALSE),'Raw Orders'!$K$5:$K$852),0.9)} | G9: =AVERAGEIFS('Raw Orders'!$K$5:$K$852,'Raw Orders'!$C$5:$C$852,$A9,'Raw Orders'!$J$5:$J$852,FALSE)
A10: LATAM | B10: LATAM | C10: =COUNTIFS('Raw Orders'!$C$5:$C$852,$A10,'Raw Orders'!$J$5:$J$852,FALSE) | D10: {=PERCENTILE(IF(('Raw Orders'!$C$5:$C$852=$A10)*('Raw Orders'!$J$5:$J$852=FALSE),'Raw Orders'!$K$5:$K$852),0.1)} | E10: {=PERCENTILE(IF(('Raw Orders'!$C$5:$C$852=$A10)*('Raw Orders'!$J$5:$J$852=FALSE),'Raw Orders'!$K$5:$K$852),0.5)} | F10: {=PERCENTILE(IF(('Raw Orders'!$C$5:$C$852=$A10)*('Raw Orders'!$J$5:$J$852=FALSE),'Raw Orders'!$K$5:$K$852),0.9)} | G10: =AVERAGEIFS('Raw Orders'!$K$5:$K$852,'Raw Orders'!$C$5:$C$852,$A10,'Raw Orders'!$J$5:$J$852,FALSE)
A13: The percentile columns are array formulas over the raw slip column, filtered to the market. Written as CSE arrays so they evaluate in any Excel version.

Sheet Region vs Market
A1: Market against regional blend
A4: region | B4: region P90 | C4: market | D4: market P90 | E4: gap vs region
A5: North America | B5: {=PERCENTILE(IF(('Raw Orders'!$B$5:$B$852=$A5)*('Raw Orders'!$J$5:$J$852=FALSE),'Raw Orders'!$K$5:$K$852),0.9)} | C5: US / Canada | D5: {=PERCENTILE(IF(('Raw Orders'!$C$5:$C$852=$C5)*('Raw Orders'!$J$5:$J$852=FALSE),'Raw Orders'!$K$5:$K$852),0.9)} | E5: =D5-B5
A6: EMEA | B6: {=PERCENTILE(IF(('Raw Orders'!$B$5:$B$852=$A6)*('Raw Orders'!$J$5:$J$852=FALSE),'Raw Orders'!$K$5:$K$852),0.9)} | C6: Europe | D6: {=PERCENTILE(IF(('Raw Orders'!$C$5:$C$852=$C6)*('Raw Orders'!$J$5:$J$852=FALSE),'Raw Orders'!$K$5:$K$852),0.9)} | E6: =D6-B6
A7: EMEA | B7: {=PERCENTILE(IF(('Raw Orders'!$B$5:$B$852=$A7)*('Raw Orders'!$J$5:$J$852=FALSE),'Raw Orders'!$K$5:$K$852),0.9)} | C7: MENA | D7: {=PERCENTILE(IF(('Raw Orders'!$C$5:$C$852=$C7)*('Raw Orders'!$J$5:$J$852=FALSE),'Raw Orders'!$K$5:$K$852),0.9)} | E7: =D7-B7
A8: APAC | B8: {=PERCENTILE(IF(('Raw Orders'!$B$5:$B$852=$A8)*('Raw Orders'!$J$5:$J$852=FALSE),'Raw Orders'!$K$5:$K$852),0.9)} | C8: Australia/SEA | D8: {=PERCENTILE(IF(('Raw Orders'!$C$5:$C$852=$C8)*('Raw Orders'!$J$5:$J$852=FALSE),'Raw Orders'!$K$5:$K$852),0.9)} | E8: =D8-B8
A9: APAC | B9: {=PERCENTILE(IF(('Raw Orders'!$B$5:$B$852=$A9)*('Raw Orders'!$J$5:$J$852=FALSE),'Raw Orders'!$K$5:$K$852),0.9)} | C9: India | D9: {=PERCENTILE(IF(('Raw Orders'!$C$5:$C$852=$C9)*('Raw Orders'!$J$5:$J$852=FALSE),'Raw Orders'!$K$5:$K$852),0.9)} | E9: =D9-B9
A10: LATAM | B10: {=PERCENTILE(IF(('Raw Orders'!$B$5:$B$852=$A10)*('Raw Orders'!$J$5:$J$852=FALSE),'Raw Orders'!$K$5:$K$852),0.9)} | C10: LATAM | D10: {=PERCENTILE(IF(('Raw Orders'!$C$5:$C$852=$C10)*('Raw Orders'!$J$5:$J$852=FALSE),'Raw Orders'!$K$5:$K$852),0.9)} | E10: =D10-B10

Sheet Lookback
A1: Conversion lookback
A4: region | B4: month | C4: expected MW | D4: actual MW | E4: realization | F4: bias MW | G4: cumulative bias MW
A5: North America | B5: 45292 | C5: =SUMIFS('Raw Orders'!$E$5:$E$852,'Raw Orders'!$B$5:$B$852,$A5,'Raw Orders'!$H$5:$H$852,$B5) | D5: =SUMIFS('Raw Orders'!$E$5:$E$852,'Raw Orders'!$B$5:$B$852,$A5,'Raw Orders'!$I$5:$I$852,$B5,'Raw Orders'!$J$5:$J$852,FALSE) | E5: =IF(C5=0,"",D5/C5) | F5: =D5-C5 | G5: =SUM($F$5:$F5)
A6: North America | B6: 45323 | C6: =SUMIFS('Raw Orders'!$E$5:$E$852,'Raw Orders'!$B$5:$B$852,$A6,'Raw Orders'!$H$5:$H$852,$B6) | D6: =SUMIFS('Raw Orders'!$E$5:$E$852,'Raw Orders'!$B$5:$B$852,$A6,'Raw Orders'!$I$5:$I$852,$B6,'Raw Orders'!$J$5:$J$852,FALSE) | E6: =IF(C6=0,"",D6/C6) | F6: =D6-C6 | G6: =SUM($F$5:$F6)
A7: North America | B7: 45352 | C7: =SUMIFS('Raw Orders'!$E$5:$E$852,'Raw Orders'!$B$5:$B$852,$A7,'Raw Orders'!$H$5:$H$852,$B7) | D7: =SUMIFS('Raw Orders'!$E$5:$E$852,'Raw Orders'!$B$5:$B$852,$A7,'Raw Orders'!$I$5:$I$852,$B7,'Raw Orders'!$J$5:$J$852,FALSE) | E7: =IF(C7=0,"",D7/C7) | F7: =D7-C7 | G7: =SUM($F$5:$F7)
A8: North America | B8: 45383 | C8: =SUMIFS('Raw Orders'!$E$5:$E$852,'Raw Orders'!$B$5:$B$852,$A8,'Raw Orders'!$H$5:$H$852,$B8) | D8: =SUMIFS('Raw Orders'!$E$5:$E$852,'Raw Orders'!$B$5:$B$852,$A8,'Raw Orders'!$I$5:$I$852,$B8,'Raw Orders'!$J$5:$J$852,FALSE) | E8: =IF(C8=0,"",D8/C8) | F8: =D8-C8 | G8: =SUM($F$5:$F8)
A9: North America | B9: 45413 | C9: =SUMIFS('Raw Orders'!$E$5:$E$852,'Raw Orders'!$B$5:$B$852,$A9,'Raw Orders'!$H$5:$H$852,$B9) | D9: =SUMIFS('Raw Orders'!$E$5:$E$852,'Raw Orders'!$B$5:$B$852,$A9,'Raw Orders'!$I$5:$I$852,$B9,'Raw Orders'!$J$5:$J$852,FALSE) | E9: =IF(C9=0,"",D9/C9) | F9: =D9-C9 | G9: =SUM($F$5:$F9)
A10: North America | B10: 45444 | C10: =SUMIFS('Raw Orders'!$E$5:$E$852,'Raw Orders'!$B$5:$B$852,$A10,'Raw Orders'!$H$5:$H$852,$B10) | D10: =SUMIFS('Raw Orders'!$E$5:$E$852,'Raw Orders'!$B$5:$B$852,$A10,'Raw Orders'!$I$5:$I$852,$B10,'Raw Orders'!$J$5:$J$852,FALSE) | E10: =IF(C10=0,"",D10/C10) | F10: =D10-C10 | G10: =SUM($F$5:$F10)
A11: North America | B11: 45474 | C11: =SUMIFS('Raw Orders'!$E$5:$E$852,'Raw Orders'!$B$5:$B$852,$A11,'Raw Orders'!$H$5:$H$852,$B11) | D11: =SUMIFS('Raw Orders'!$E$5:$E$852,'Raw Orders'!$B$5:$B$852,$A11,'Raw Orders'!$I$5:$I$852,$B11,'Raw Orders'!$J$5:$J$852,FALSE) | E11: =IF(C11=0,"",D11/C11) | F11: =D11-C11 | G11: =SUM($F$5:$F11)
A12: North America | B12: 45505 | C12: =SUMIFS('Raw Orders'!$E$5:$E$852,'Raw Orders'!$B$5:$B$852,$A12,'Raw Orders'!$H$5:$H$852,$B12) | D12: =SUMIFS('Raw Orders'!$E$5:$E$852,'Raw Orders'!$B$5:$B$852,$A12,'Raw Orders'!$I$5:$I$852,$B12,'Raw Orders'!$J$5:$J$852,FALSE) | E12: =IF(C12=0,"",D12/C12) | F12: =D12-C12 | G12: =SUM($F$5:$F12)
A13: North America | B13: 45536 | C13: =SUMIFS('Raw Orders'!$E$5:$E$852,'Raw Orders'!$B$5:$B$852,$A13,'Raw Orders'!$H$5:$H$852,$B13) | D13: =SUMIFS('Raw Orders'!$E$5:$E$852,'Raw Orders'!$B$5:$B$852,$A13,'Raw Orders'!$I$5:$I$852,$B13,'Raw Orders'!$J$5:$J$852,FALSE) | E13: =IF(C13=0,"",D13/C13) | F13: =D13-C13 | G13: =SUM($F$5:$F13)
A14: North America | B14: 45566 | C14: =SUMIFS('Raw Orders'!$E$5:$E$852,'Raw Orders'!$B$5:$B$852,$A14,'Raw Orders'!$H$5:$H$852,$B14) | D14: =SUMIFS('Raw Orders'!$E$5:$E$852,'Raw Orders'!$B$5:$B$852,$A14,'Raw Orders'!$I$5:$I$852,$B14,'Raw Orders'!$J$5:$J$852,FALSE) | E14: =IF(C14=0,"",D14/C14) | F14: =D14-C14 | G14: =SUM($F$5:$F14)
A15: North America | B15: 45597 | C15: =SUMIFS('Raw Orders'!$E$5:$E$852,'Raw Orders'!$B$5:$B$852,$A15,'Raw Orders'!$H$5:$H$852,$B15) | D15: =SUMIFS('Raw Orders'!$E$5:$E$852,'Raw Orders'!$B$5:$B$852,$A15,'Raw Orders'!$I$5:$I$852,$B15,'Raw Orders'!$J$5:$J$852,FALSE) | E15: =IF(C15=0,"",D15/C15) | F15: =D15-C15 | G15: =SUM($F$5:$F15)
A16: North America | B16: 45627 | C16: =SUMIFS('Raw Orders'!$E$5:$E$852,'Raw Orders'!$B$5:$B$852,$A16,'Raw Orders'!$H$5:$H$852,$B16) | D16: =SUMIFS('Raw Orders'!$E$5:$E$852,'Raw Orders'!$B$5:$B$852,$A16,'Raw Orders'!$I$5:$I$852,$B16,'Raw Orders'!$J$5:$J$852,FALSE) | E16: =IF(C16=0,"",D16/C16) | F16: =D16-C16 | G16: =SUM($F$5:$F16)
... A28: North America | B28: 45992 | C28: =SUMIFS('Raw Orders'!$E$5:$E$852,'Raw Orders'!$B$5:$B$852,$A28,'Raw Orders'!$H$5:$H$852,$B28) | D28: =SUMIFS('Raw Orders'!$E$5:$E$852,'Raw Orders'!$B$5:$B$852,$A28,'Raw Orders'!$I$5:$I$852,$B28,'Raw Orders'!$J$5:$J$852,FALSE) | E28: =IF(C28=0,"",D28/C28) | F28: =D28-C28 | G28: =SUM($F$5:$F28)
A29: EMEA | B29: 45292 | C29: =SUMIFS('Raw Orders'!$E$5:$E$852,'Raw Orders'!$B$5:$B$852,$A29,'Raw Orders'!$H$5:$H$852,$B29) | D29: =SUMIFS('Raw Orders'!$E$5:$E$852,'Raw Orders'!$B$5:$B$852,$A29,'Raw Orders'!$I$5:$I$852,$B29,'Raw Orders'!$J$5:$J$852,FALSE) | E29: =IF(C29=0,"",D29/C29) | F29: =D29-C29 | G29: =SUM($F$29:$F29)
A30: EMEA | B30: 45323 | C30: =SUMIFS('Raw Orders'!$E$5:$E$852,'Raw Orders'!$B$5:$B$852,$A30,'Raw Orders'!$H$5:$H$852,$B30) | D30: =SUMIFS('Raw Orders'!$E$5:$E$852,'Raw Orders'!$B$5:$B$852,$A30,'Raw Orders'!$I$5:$I$852,$B30,'Raw Orders'!$J$5:$J$852,FALSE) | E30: =IF(C30=0,"",D30/C30) | F30: =D30-C30 | G30: =SUM($F$29:$F30)
A31: EMEA | B31: 45352 | C31: =SUMIFS('Raw Orders'!$E$5:$E$852,'Raw Orders'!$B$5:$B$852,$A31,'Raw Orders'!$H$5:$H$852,$B31) | D31: =SUMIFS('Raw Orders'!$E$5:$E$852,'Raw Orders'!$B$5:$B$852,$A31,'Raw Orders'!$I$5:$I$852,$B31,'Raw Orders'!$J$5:$J$852,FALSE) | E31: =IF(C31=0,"",D31/C31) | F31: =D31-C31 | G31: =SUM($F$29:$F31)
A32: EMEA | B32: 45383 | C32: =SUMIFS('Raw Orders'!$E$5:$E$852,'Raw Orders'!$B$5:$B$852,$A32,'Raw Orders'!$H$5:$H$852,$B32) | D32: =SUMIFS('Raw Orders'!$E$5:$E$852,'Raw Orders'!$B$5:$B$852,$A32,'Raw Orders'!$I$5:$I$852,$B32,'Raw Orders'!$J$5:$J$852,FALSE) | E32: =IF(C32=0,"",D32/C32) | F32: =D32-C32 | G32: =SUM($F$29:$F32)
A33: EMEA | B33: 45413 | C33: =SUMIFS('Raw Orders'!$E$5:$E$852,'Raw Orders'!$B$5:$B$852,$A33,'Raw Orders'!$H$5:$H$852,$B33) | D33: =SUMIFS('Raw Orders'!$E$5:$E$852,'Raw Orders'!$B$5:$B$852,$A33,'Raw Orders'!$I$5:$I$852,$B33,'Raw Orders'!$J$5:$J$852,FALSE) | E33: =IF(C33=0,"",D33/C33) | F33: =D33-C33 | G33: =SUM($F$29:$F33)
A34: EMEA | B34: 45444 | C34: =SUMIFS('Raw Orders'!$E$5:$E$852,'Raw Orders'!$B$5:$B$852,$A34,'Raw Orders'!$H$5:$H$852,$B34) | D34: =SUMIFS('Raw Orders'!$E$5:$E$852,'Raw Orders'!$B$5:$B$852,$A34,'Raw Orders'!$I$5:$I$852,$B34,'Raw Orders'!$J$5:$J$852,FALSE) | E34: =IF(C34=0,"",D34/C34) | F34: =D34-C34 | G34: =SUM($F$29:$F34)
A35: EMEA | B35: 45474 | C35: =SUMIFS('Raw Orders'!$E$5:$E$852,'Raw Orders'!$B$5:$B$852,$A35,'Raw Orders'!$H$5:$H$852,$B35) | D35: =SUMIFS('Raw Orders'!$E$5:$E$852,'Raw Orders'!$B$5:$B$852,$A35,'Raw Orders'!$I$5:$I$852,$B35,'Raw Orders'!$J$5:$J$852,FALSE) | E35: =IF(C35=0,"",D35/C35) | F35: =D35-C35 | G35: =SUM($F$29:$F35)
A36: EMEA | B36: 45505 | C36: =SUMIFS('Raw Orders'!$E$5:$E$852,'Raw Orders'!$B$5:$B$852,$A36,'Raw Orders'!$H$5:$H$852,$B36) | D36: =SUMIFS('Raw Orders'!$E$5:$E$852,'Raw Orders'!$B$5:$B$852,$A36,'Raw Orders'!$I$5:$I$852,$B36,'Raw Orders'!$J$5:$J$852,FALSE) | E36: =IF(C36=0,"",D36/C36) | F36: =D36-C36 | G36: =SUM($F$29:$F36)
A37: EMEA | B37: 45536 | C37: =SUMIFS('Raw Orders'!$E$5:$E$852,'Raw Orders'!$B$5:$B$852,$A37,'Raw Orders'!$H$5:$H$852,$B37) | D37: =SUMIFS('Raw Orders'!$E$5:$E$852,'Raw Orders'!$B$5:$B$852,$A37,'Raw Orders'!$I$5:$I$852,$B37,'Raw Orders'!$J$5:$J$852,FALSE) | E37: =IF(C37=0,"",D37/C37) | F37: =D37-C37 | G37: =SUM($F$29:$F37)
A38: EMEA | B38: 45566 | C38: =SUMIFS('Raw Orders'!$E$5:$E$852,'Raw Orders'!$B$5:$B$852,$A38,'Raw Orders'!$H$5:$H$852,$B38) | D38: =SUMIFS('Raw Orders'!$E$5:$E$852,'Raw Orders'!$B$5:$B$852,$A38,'Raw Orders'!$I$5:$I$852,$B38,'Raw Orders'!$J$5:$J$852,FALSE) | E38: =IF(C38=0,"",D38/C38) | F38: =D38-C38 | G38: =SUM($F$29:$F38)
A39: EMEA | B39: 45597 | C39: =SUMIFS('Raw Orders'!$E$5:$E$852,'Raw Orders'!$B$5:$B$852,$A39,'Raw Orders'!$H$5:$H$852,$B39) | D39: =SUMIFS('Raw Orders'!$E$5:$E$852,'Raw Orders'!$B$5:$B$852,$A39,'Raw Orders'!$I$5:$I$852,$B39,'Raw Orders'!$J$5:$J$852,FALSE) | E39: =IF(C39=0,"",D39/C39) | F39: =D39-C39 | G39: =SUM($F$29:$F39)
A40: EMEA | B40: 45627 | C40: =SUMIFS('Raw Orders'!$E$5:$E$852,'Raw Orders'!$B$5:$B$852,$A40,'Raw Orders'!$H$5:$H$852,$B40) | D40: =SUMIFS('Raw Orders'!$E$5:$E$852,'Raw Orders'!$B$5:$B$852,$A40,'Raw Orders'!$I$5:$I$852,$B40,'Raw Orders'!$J$5:$J$852,FALSE) | E40: =IF(C40=0,"",D40/C40) | F40: =D40-C40 | G40: =SUM($F$29:$F40)
... A52: EMEA | B52: 45992 | C52: =SUMIFS('Raw Orders'!$E$5:$E$852,'Raw Orders'!$B$5:$B$852,$A52,'Raw Orders'!$H$5:$H$852,$B52) | D52: =SUMIFS('Raw Orders'!$E$5:$E$852,'Raw Orders'!$B$5:$B$852,$A52,'Raw Orders'!$I$5:$I$852,$B52,'Raw Orders'!$J$5:$J$852,FALSE) | E52: =IF(C52=0,"",D52/C52) | F52: =D52-C52 | G52: =SUM($F$29:$F52)
A53: APAC | B53: 45292 | C53: =SUMIFS('Raw Orders'!$E$5:$E$852,'Raw Orders'!$B$5:$B$852,$A53,'Raw Orders'!$H$5:$H$852,$B53) | D53: =SUMIFS('Raw Orders'!$E$5:$E$852,'Raw Orders'!$B$5:$B$852,$A53,'Raw Orders'!$I$5:$I$852,$B53,'Raw Orders'!$J$5:$J$852,FALSE) | E53: =IF(C53=0,"",D53/C53) | F53: =D53-C53 | G53: =SUM($F$53:$F53)
A54: APAC | B54: 45323 | C54: =SUMIFS('Raw Orders'!$E$5:$E$852,'Raw Orders'!$B$5:$B$852,$A54,'Raw Orders'!$H$5:$H$852,$B54) | D54: =SUMIFS('Raw Orders'!$E$5:$E$852,'Raw Orders'!$B$5:$B$852,$A54,'Raw Orders'!$I$5:$I$852,$B54,'Raw Orders'!$J$5:$J$852,FALSE) | E54: =IF(C54=0,"",D54/C54) | F54: =D54-C54 | G54: =SUM($F$53:$F54)
A55: APAC | B55: 45352 | C55: =SUMIFS('Raw Orders'!$E$5:$E$852,'Raw Orders'!$B$5:$B$852,$A55,'Raw Orders'!$H$5:$H$852,$B55) | D55: =SUMIFS('Raw Orders'!$E$5:$E$852,'Raw Orders'!$B$5:$B$852,$A55,'Raw Orders'!$I$5:$I$852,$B55,'Raw Orders'!$J$5:$J$852,FALSE) | E55: =IF(C55=0,"",D55/C55) | F55: =D55-C55 | G55: =SUM($F$53:$F55)
A56: APAC | B56: 45383 | C56: =SUMIFS('Raw Orders'!$E$5:$E$852,'Raw Orders'!$B$5:$B$852,$A56,'Raw Orders'!$H$5:$H$852,$B56) | D56: =SUMIFS('Raw Orders'!$E$5:$E$852,'Raw Orders'!$B$5:$B$852,$A56,'Raw Orders'!$I$5:$I$852,$B56,'Raw Orders'!$J$5:$J$852,FALSE) | E56: =IF(C56=0,"",D56/C56) | F56: =D56-C56 | G56: =SUM($F$53:$F56)
A57: APAC | B57: 45413 | C57: =SUMIFS('Raw Orders'!$E$5:$E$852,'Raw Orders'!$B$5:$B$852,$A57,'Raw Orders'!$H$5:$H$852,$B57) | D57: =SUMIFS('Raw Orders'!$E$5:$E$852,'Raw Orders'!$B$5:$B$852,$A57,'Raw Orders'!$I$5:$I$852,$B57,'Raw Orders'!$J$5:$J$852,FALSE) | E57: =IF(C57=0,"",D57/C57) | F57: =D57-C57 | G57: =SUM($F$53:$F57)
A58: APAC | B58: 45444 | C58: =SUMIFS('Raw Orders'!$E$5:$E$852,'Raw Orders'!$B$5:$B$852,$A58,'Raw Orders'!$H$5:$H$852,$B58) | D58: =SUMIFS('Raw Orders'!$E$5:$E$852,'Raw Orders'!$B$5:$B$852,$A58,'Raw Orders'!$I$5:$I$852,$B58,'Raw Orders'!$J$5:$J$852,FALSE) | E58: =IF(C58=0,"",D58/C58) | F58: =D58-C58 | G58: =SUM($F$53:$F58)
A59: APAC | B59: 45474 | C59: =SUMIFS('Raw Orders'!$E$5:$E$852,'Raw Orders'!$B$5:$B$852,$A59,'Raw Orders'!$H$5:$H$852,$B59) | D59: =SUMIFS('Raw Orders'!$E$5:$E$852,'Raw Orders'!$B$5:$B$852,$A59,'Raw Orders'!$I$5:$I$852,$B59,'Raw Orders'!$J$5:$J$852,FALSE) | E59: =IF(C59=0,"",D59/C59) | F59: =D59-C59 | G59: =SUM($F$53:$F59)
A60: APAC | B60: 45505 | C60: =SUMIFS('Raw Orders'!$E$5:$E$852,'Raw Orders'!$B$5:$B$852,$A60,'Raw Orders'!$H$5:$H$852,$B60) | D60: =SUMIFS('Raw Orders'!$E$5:$E$852,'Raw Orders'!$B$5:$B$852,$A60,'Raw Orders'!$I$5:$I$852,$B60,'Raw Orders'!$J$5:$J$852,FALSE) | E60: =IF(C60=0,"",D60/C60) | F60: =D60-C60 | G60: =SUM($F$53:$F60)
A61: APAC | B61: 45536 | C61: =SUMIFS('Raw Orders'!$E$5:$E$852,'Raw Orders'!$B$5:$B$852,$A61,'Raw Orders'!$H$5:$H$852,$B61) | D61: =SUMIFS('Raw Orders'!$E$5:$E$852,'Raw Orders'!$B$5:$B$852,$A61,'Raw Orders'!$I$5:$I$852,$B61,'Raw Orders'!$J$5:$J$852,FALSE) | E61: =IF(C61=0,"",D61/C61) | F61: =D61-C61 | G61: =SUM($F$53:$F61)
A62: APAC | B62: 45566 | C62: =SUMIFS('Raw Orders'!$E$5:$E$852,'Raw Orders'!$B$5:$B$852,$A62,'Raw Orders'!$H$5:$H$852,$B62) | D62: =SUMIFS('Raw Orders'!$E$5:$E$852,'Raw Orders'!$B$5:$B$852,$A62,'Raw Orders'!$I$5:$I$852,$B62,'Raw Orders'!$J$5:$J$852,FALSE) | E62: =IF(C62=0,"",D62/C62) | F62: =D62-C62 | G62: =SUM($F$53:$F62)
A63: APAC | B63: 45597 | C63: =SUMIFS('Raw Orders'!$E$5:$E$852,'Raw Orders'!$B$5:$B$852,$A63,'Raw Orders'!$H$5:$H$852,$B63) | D63: =SUMIFS('Raw Orders'!$E$5:$E$852,'Raw Orders'!$B$5:$B$852,$A63,'Raw Orders'!$I$5:$I$852,$B63,'Raw Orders'!$J$5:$J$852,FALSE) | E63: =IF(C63=0,"",D63/C63) | F63: =D63-C63 | G63: =SUM($F$53:$F63)
A64: APAC | B64: 45627 | C64: =SUMIFS('Raw Orders'!$E$5:$E$852,'Raw Orders'!$B$5:$B$852,$A64,'Raw Orders'!$H$5:$H$852,$B64) | D64: =SUMIFS('Raw Orders'!$E$5:$E$852,'Raw Orders'!$B$5:$B$852,$A64,'Raw Orders'!$I$5:$I$852,$B64,'Raw Orders'!$J$5:$J$852,FALSE) | E64: =IF(C64=0,"",D64/C64) | F64: =D64-C64 | G64: =SUM($F$53:$F64)
...

Sheet Commitment
A1: Material committed against backlog
A4: region | B4: closing backlog ($) | C4: at 100% | D4: at 95% | E4: at 90% | F4: at 85% | G4: at 80% | H4: at 75% | I4: at 70% | J4: exposure 100% vs 70%
A5: North America | B5: =SUMIFS('Raw Orders'!$F$5:$F$852,'Raw Orders'!$B$5:$B$852,$A5,'Raw Orders'!$D$5:$D$852,"<="&DATE(2025,12,1))-SUMIFS('Raw Orders'!$F$5:$F$852,'Raw Orders'!$B$5:$B$852,$A5,'Raw Orders'!$I$5:$I$852,"<="&DATE(2025,12,1),'Raw Orders'!$J$5:$J$852,FALSE) | C5: =$B5*0.5*1.0 | D5: =$B5*0.5*0.95 | E5: =$B5*0.5*0.9 | F5: =$B5*0.5*0.85 | G5: =$B5*0.5*0.8 | H5: =$B5*0.5*0.75 | I5: =$B5*0.5*0.7 | J5: =C5-I5
A6: EMEA | B6: =SUMIFS('Raw Orders'!$F$5:$F$852,'Raw Orders'!$B$5:$B$852,$A6,'Raw Orders'!$D$5:$D$852,"<="&DATE(2025,12,1))-SUMIFS('Raw Orders'!$F$5:$F$852,'Raw Orders'!$B$5:$B$852,$A6,'Raw Orders'!$I$5:$I$852,"<="&DATE(2025,12,1),'Raw Orders'!$J$5:$J$852,FALSE) | C6: =$B6*0.5*1.0 | D6: =$B6*0.5*0.95 | E6: =$B6*0.5*0.9 | F6: =$B6*0.5*0.85 | G6: =$B6*0.5*0.8 | H6: =$B6*0.5*0.75 | I6: =$B6*0.5*0.7 | J6: =C6-I6
A7: APAC | B7: =SUMIFS('Raw Orders'!$F$5:$F$852,'Raw Orders'!$B$5:$B$852,$A7,'Raw Orders'!$D$5:$D$852,"<="&DATE(2025,12,1))-SUMIFS('Raw Orders'!$F$5:$F$852,'Raw Orders'!$B$5:$B$852,$A7,'Raw Orders'!$I$5:$I$852,"<="&DATE(2025,12,1),'Raw Orders'!$J$5:$J$852,FALSE) | C7: =$B7*0.5*1.0 | D7: =$B7*0.5*0.95 | E7: =$B7*0.5*0.9 | F7: =$B7*0.5*0.85 | G7: =$B7*0.5*0.8 | H7: =$B7*0.5*0.75 | I7: =$B7*0.5*0.7 | J7: =C7-I7
A8: LATAM | B8: =SUMIFS('Raw Orders'!$F$5:$F$852,'Raw Orders'!$B$5:$B$852,$A8,'Raw Orders'!$D$5:$D$852,"<="&DATE(2025,12,1))-SUMIFS('Raw Orders'!$F$5:$F$852,'Raw Orders'!$B$5:$B$852,$A8,'Raw Orders'!$I$5:$I$852,"<="&DATE(2025,12,1),'Raw Orders'!$J$5:$J$852,FALSE) | C8: =$B8*0.5*1.0 | D8: =$B8*0.5*0.95 | E8: =$B8*0.5*0.9 | F8: =$B8*0.5*0.85 | G8: =$B8*0.5*0.8 | H8: =$B8*0.5*0.75 | I8: =$B8*0.5*0.7 | J8: =C8-I8
A9: Total | B9: =SUM(B5:B8) | C9: =SUM(C5:C8) | D9: =SUM(D5:D8) | E9: =SUM(E5:E8) | F9: =SUM(F5:F8) | G9: =SUM(G5:G8) | H9: =SUM(H5:H8) | I9: =SUM(I5:I8) | J9: =SUM(J5:J8)

Sheet MC Forward
A1: Forward material requirement
G3: =high - low, the width of the stated 80% interval
A4: month | B4: already booked ($) | C4: not yet booked ($) | D4: expected total ($) | E4: low (P10) | F4: high (P90) | G4: spread | H4: firm share
A5: 46023 | B5: 25722250 | C5: 0 | D5: 25722250 | E5: 20862045 | F5: 30696345 | G5: =F5-E5 | H5: =IF(D5=0,"",B5/D5)
A6: 46054 | B6: 27842025 | C6: 0 | D6: 27842025 | E6: 22772185 | F6: 33049310 | G6: =F6-E6 | H6: =IF(D6=0,"",B6/D6)
A7: 46082 | B7: 26726925 | C7: 0 | D7: 26726925 | E7: 21698590 | F7: 32079240 | G7: =F7-E7 | H7: =IF(D7=0,"",B7/D7)
A8: 46113 | B8: 31557600 | C8: 0 | D8: 31557600 | E8: 25154060 | F8: 37821440 | G8: =F8-E8 | H8: =IF(D8=0,"",B8/D8)
A9: 46143 | B9: 27924400 | C9: 0 | D9: 27924400 | E9: 21925070 | F9: 34400165 | G9: =F9-E9 | H9: =IF(D9=0,"",B9/D9)
A10: 46174 | B10: 23644350 | C10: 6328700 | D10: 30413900 | E10: 24160670 | F10: 38386505 | G10: =F10-E10 | H10: =IF(D10=0,"",B10/D10)
A11: 46204 | B11: 23876950 | C11: 9974100 | D11: 34021800 | E11: 24824530 | F11: 42868480 | G11: =F11-E11 | H11: =IF(D11=0,"",B11/D11)
A12: 46235 | B12: 11650950 | C12: 13359400 | D12: 25754125 | E12: 18872265 | F12: 35212555 | G12: =F12-E12 | H12: =IF(D12=0,"",B12/D12)
A13: 46266 | B13: 11495400 | C13: 16164000 | D13: 28124675 | E13: 21182975 | F13: 37703520 | G13: =F13-E13 | H13: =IF(D13=0,"",B13/D13)
A14: 46296 | B14: 11058775 | C14: 18684650 | D14: 30392875 | E14: 22971730 | F14: 39756830 | G14: =F14-E14 | H14: =IF(D14=0,"",B14/D14)
A15: 46327 | B15: 11503225 | C15: 20760100 | D15: 32706625 | E15: 25005335 | F15: 42594825 | G15: =F15-E15 | H15: =IF(D15=0,"",B15/D15)
A16: 46357 | B16: 8886775 | C16: 22913000 | D16: 32155575 | E16: 24412585 | F16: 41988865 | G16: =F16-E16 | H16: =IF(D16=0,"",B16/D16)
A18: Already booked and not yet booked are medians of two separate simulations, so they do not sum exactly to the expected total, which is the median of the combined draw. Medians are not additive.

Sheet MC Coverage
A1: Walk-forward interval coverage
A2: Each row re-runs the model at a past cutoff, using only what was known at that cutoff, and scores the forecast against what the month turned out to be.
A4: cutoff | B4: month | C4: months ahead | D4: actual ($) | E4: P10 | F4: P25 | G4: P50 | H4: P75 | I4: P90 | J4: spread (P90-P10) | K4: inside 80% | L4: inside 50%
A5: 45566 | B5: 45597 | C5: 1 | D5: 26443500 | E5: 25846990 | F5: 28271838 | G5: 31367650 | H5: 34047862 | I5: 36793645 | J5: =I5-E5 | K5: =IF(AND(D5>=E5,D5<=I5),1,0) | L5: =IF(AND(D5>=F5,D5<=H5),1,0)
A6: 45566 | B6: 45627 | C6: 2 | D6: 26693350 | E6: 22177840 | F6: 25168312 | G6: 28067975 | H6: 31185288 | I6: 34008680 | J6: =I6-E6 | K6: =IF(AND(D6>=E6,D6<=I6),1,0) | L6: =IF(AND(D6>=F6,D6<=H6),1,0)
A7: 45566 | B7: 45658 | C7: 3 | D7: 23339950 | E7: 22741925 | F7: 25133150 | G7: 27563725 | H7: 30288025 | I7: 32469990 | J7: =I7-E7 | K7: =IF(AND(D7>=E7,D7<=I7),1,0) | L7: =IF(AND(D7>=F7,D7<=H7),1,0)
A8: 45566 | B8: 45689 | C8: 4 | D8: 17299300 | E8: 11687105 | F8: 13444088 | G8: 15699750 | H8: 18386062 | I8: 20719030 | J8: =I8-E8 | K8: =IF(AND(D8>=E8,D8<=I8),1,0) | L8: =IF(AND(D8>=F8,D8<=H8),1,0)
A9: 45566 | B9: 45717 | C9: 5 | D9: 20974650 | E9: 14208260 | F9: 15819212 | G9: 17382175 | H9: 19295788 | I9: 20935610 | J9: =I9-E9 | K9: =IF(AND(D9>=E9,D9<=I9),1,0) | L9: =IF(AND(D9>=F9,D9<=H9),1,0)
A10: 45566 | B10: 45748 | C10: 6 | D10: 20108700 | E10: 16054860 | F10: 17635075 | G10: 19486750 | H10: 21435625 | I10: 23242365 | J10: =I10-E10 | K10: =IF(AND(D10>=E10,D10<=I10),1,0) | L10: =IF(AND(D10>=F10,D10<=H10),1,0)
A11: 45597 | B11: 45627 | C11: 1 | D11: 26693350 | E11: 23520885 | F11: 25411988 | G11: 27481400 | H11: 29392550 | I11: 31130250 | J11: =I11-E11 | K11: =IF(AND(D11>=E11,D11<=I11),1,0) | L11: =IF(AND(D11>=F11,D11<=H11),1,0)
A12: 45597 | B12: 45658 | C12: 2 | D12: 23339950 | E12: 26486200 | F12: 28702875 | G12: 31301000 | H12: 33877125 | I12: 36422825 | J12: =I12-E12 | K12: =IF(AND(D12>=E12,D12<=I12),1,0) | L12: =IF(AND(D12>=F12,D12<=H12),1,0)
A13: 45597 | B13: 45689 | C13: 3 | D13: 17299300 | E13: 12725925 | F13: 14855038 | G13: 16885175 | H13: 18912062 | I13: 21293820 | J13: =I13-E13 | K13: =IF(AND(D13>=E13,D13<=I13),1,0) | L13: =IF(AND(D13>=F13,D13<=H13),1,0)
A14: 45597 | B14: 45717 | C14: 4 | D14: 20974650 | E14: 15710290 | F14: 17301625 | G14: 19068400 | H14: 20945125 | I14: 22597140 | J14: =I14-E14 | K14: =IF(AND(D14>=E14,D14<=I14),1,0) | L14: =IF(AND(D14>=F14,D14<=H14),1,0)
A15: 45597 | B15: 45748 | C15: 5 | D15: 22132100 | E15: 16847575 | F15: 18347438 | G15: 20305275 | H15: 22412088 | I15: 24175330 | J15: =I15-E15 | K15: =IF(AND(D15>=E15,D15<=I15),1,0) | L15: =IF(AND(D15>=F15,D15<=H15),1,0)
A16: 45597 | B16: 45778 | C16: 6 | D16: 20321950 | E16: 15994160 | F16: 17894175 | G16: 19790150 | H16: 21854550 | I16: 23495310 | J16: =I16-E16 | K16: =IF(AND(D16>=E16,D16<=I16),1,0) | L16: =IF(AND(D16>=F16,D16<=H16),1,0)
... A52: 45778 | B52: 45962 | C52: 6 | D52: 17684700 | E52: 14317050 | F52: 16683462 | G52: 19416900 | H52: 22083225 | I52: 25013575 | J52: =I52-E52 | K52: =IF(AND(D52>=E52,D52<=I52),1,0) | L52: =IF(AND(D52>=F52,D52<=H52),1,0)
A55: What the test measures
A56: Eight cutoffs, six months forward from each. That is 48 scored forecasts but only 13 distinct outcome months, because overlapping windows score the same month more than once. Everything below is measurement. No multiplier is fitted here and none is applied to the forward tab, because a sample this size would not support one.
A59: forecasts scored (n) | C59: =COUNT($K$5:$K$52)
A60: distinct outcome months | C60: =SUMPRODUCT(($B$5:$B$52<>"")/COUNTIF($B$5:$B$52,$B$5:$B$52&""))
A61: stated 80% interval, coverage achieved | C61: =AVERAGE($K$5:$K$52)
A62: stated 50% interval, coverage achieved | C62: =AVERAGE($L$5:$L$52)
A63: misses above the interval | C63: =SUMPRODUCT(--($D$5:$D$52>$I$5:$I$52))
A64: misses below the interval | C64: =SUMPRODUCT(--($D$5:$D$52<$E$5:$E$52))
A67: Coverage by how far ahead the call was made
A68: The interval is weakest one month out and holds further out, which is the reverse of the usual shape. Near-in months are dominated by a handful of large orders, and a single one moving is enough to put the month outside the band.
A71: months ahead | B71: forecasts | C71: inside 80%
A72: 1 | B72: =COUNTIFS($C$5:$C$52,A72) | C72: =AVERAGEIFS($K$5:$K$52,$C$5:$C$52,A72)
A73: 2 | B73: =COUNTIFS($C$5:$C$52,A73) | C73: =AVERAGEIFS($K$5:$K$52,$C$5:$C$52,A73)
A74: 3 | B74: =COUNTIFS($C$5:$C$52,A74) | C74: =AVERAGEIFS($K$5:$K$52,$C$5:$C$52,A74)
A75: 4 | B75: =COUNTIFS($C$5:$C$52,A75) | C75: =AVERAGEIFS($K$5:$K$52,$C$5:$C$52,A75)
A76: 5 | B76: =COUNTIFS($C$5:$C$52,A76) | C76: =AVERAGEIFS($K$5:$K$52,$C$5:$C$52,A76)
A77: 6 | B77: =COUNTIFS($C$5:$C$52,A77) | C77: =AVERAGEIFS($K$5:$K$52,$C$5:$C$52,A77)
