Workbook

Sheet Contents
A1: S&OP demand and material review - data and calculations
A3: SYNTHETIC DATA. Region names and the North America revenue weighting come from public filings and public role titles. Every order, date and dollar figure is generated. This demonstrates a method and represents no company's actual business.
A7: Tab | B7: What is on it | C7: Type
A8: Raw Orders | B8: The order book as an ERP would extract it. Values only, one row per project. | C8: source
A9: Engineered Orders | B9: Fields derived per order: material committed, slip, status, material at risk. | C9: formulas
A10: Monthly by Region | B10: Bookings, conversions, backlog and book-to-bill by region and month. | C10: formulas
A11: Slip by Market | B11: Schedule slip distribution per market, P10 / P50 / P90. | C11: formulas
A12: Region vs Market | B12: Each market's P90 against its region's blended P90. | C12: formulas
A13: Lookback | B13: Expected against actual conversion by region and month, with cumulative bias. | C13: formulas
A14: Commitment | B14: Material committed against backlog at a range of realization assumptions. | C14: formulas
A15: MC Forward | B15: Forward requirement by month. Simulated P10/P50/P90; calibrated bounds are formulas. | C15: mixed
A16: MC Calibration | B16: Walk-forward coverage test. The conformal step is worked in full, as formulas. | C16: mixed
A19: On the two model-output tabs
A20: Excel reproduces every aggregate in this workbook, including the conformal calibration, which is worked in full on the calibration tab. The one thing it cannot reasonably do is run 4,000 simulations across 895 orders, so the P10/P50/P90 columns on the two MC tabs are simulated values. Everything derived from them is a formula. The scripts are in the same repository.
A24: Material rate used throughout | C24: 0.75

Sheet Raw Orders
A1: Raw order book
A4: order_id | B4: region | C4: market | D4: booked_month | E4: mw | F4: order_value | G4: promised_months | H4: expected_conversion | I4: actual_conversion | J4: cancelled | K4: slip_months
A5: NX-00001 | B5: North America | C5: US / Canada | D5: 45292 | E5: 31.5 | F5: 2614500 | G5: 11 | H5: 45627 | I5: 45717 | J5: FALSE | K5: 2.72
A6: NX-00002 | B6: North America | C6: US / Canada | D6: 45292 | E6: 23.5 | F6: 1950500 | G6: 7 | H6: 45505 | I6: 45536 | J6: FALSE | K6: 1.33
A7: NX-00003 | B7: North America | C7: US / Canada | D7: 45292 | E7: 58.2 | F7: 4830600 | G7: 11 | H7: 45627 | I7: 45627 | J7: FALSE | K7: 0.07
A8: NX-00004 | B8: North America | C8: US / Canada | D8: 45292 | E8: 7 | F8: 581000 | G8: 7 | H8: 45505 | I8: 45597 | J8: FALSE | K8: 2.58
A9: NX-00005 | B9: North America | C9: US / Canada | D9: 45292 | E9: 6 | F9: 498000 | G9: 5 | H9: 45444 | I9: 45444 | J9: FALSE | K9: 0
A10: NX-00006 | B10: North America | C10: US / Canada | D10: 45292 | E10: 38.4 | F10: 3187200 | G10: 11 | H10: 45627 | I10: 45627 | J10: FALSE | K10: 0
A11: NX-00007 | B11: North America | C11: US / Canada | D11: 45292 | E11: 5.8 | F11: 481400 | G11: 7 | H11: 45505 | I11: 45505 | J11: FALSE | K11: 0
A12: NX-00008 | B12: North America | C12: US / Canada | D12: 45292 | E12: 9.9 | F12: 821700 | G12: 5 | H12: 45444 | I12: 45566 | J12: FALSE | K12: 3.62
A13: NX-00009 | B13: North America | C13: US / Canada | D13: 45292 | E13: 4.5 | F13: 373500 | G13: 11 | H13: 45627 | I13: 45658 | J13: FALSE | K13: 0.52
A14: NX-00010 | B14: North America | C14: US / Canada | D14: 45292 | E14: 25.5 | F14: 2116500 | G14: 7 | H14: 45505 | I14: 45597 | J14: FALSE | K14: 2.53
A15: NX-00011 | B15: North America | C15: US / Canada | D15: 45292 | E15: 14.3 | F15: 1186900 | G15: 11 | H15: 45627 | I15: 45717 | J15: FALSE | K15: 3.42
A16: NX-00012 | B16: North America | C16: US / Canada | D16: 45292 | E16: 21.5 | F16: 1784500 | G16: 9 | H16: 45566 | I16: 45689 | J16: FALSE | K16: 3.56
... A69: NX-00065 | B69: North America | C69: US / Canada | D69: 45352 | E69: 30.1 | F69: 2498300 | G69: 7 | H69: 45566 | I69: 45627 | J69: FALSE | K69: 1.74
A70: NX-00066 | B70: North America | C70: US / Canada | D70: 45352 | E70: 8.6 | F70: 713800 | G70: 5 | H70: 45505 | J70: TRUE | K70: 0.22
A71: NX-00067 | B71: North America | C71: US / Canada | D71: 45352 | E71: 14.6 | F71: 1211800 | G71: 8 | H71: 45597 | I71: 45627 | J71: FALSE | K71: 0.61
A72: NX-00068 | B72: North America | C72: US / Canada | D72: 45352 | E72: 45.4 | F72: 3768200 | G72: 9 | H72: 45627 | I72: 45627 | J72: FALSE | K72: 0.01
A73: NX-00069 | B73: North America | C73: US / Canada | D73: 45352 | E73: 44 | F73: 3652000 | G73: 5 | H73: 45505 | I73: 45505 | J73: FALSE | K73: 0.13
A74: NX-00070 | B74: North America | C74: US / Canada | D74: 45352 | E74: 6.4 | F74: 531200 | G74: 6 | H74: 45536 | I74: 45536 | J74: FALSE | K74: 0.08
A75: NX-00071 | B75: North America | C75: US / Canada | D75: 45352 | E75: 35 | F75: 2905000 | G75: 7 | H75: 45566 | I75: 45597 | J75: FALSE | K75: 0.78
A76: NX-00072 | B76: North America | C76: US / Canada | D76: 45352 | E76: 31.2 | F76: 2589600 | G76: 10 | H76: 45658 | I76: 45658 | J76: FALSE | K76: 0
A77: NX-00073 | B77: North America | C77: US / Canada | D77: 45352 | E77: 29.9 | F77: 2481700 | G77: 7 | H77: 45566 | I77: 45566 | J77: FALSE | K77: 0
A78: NX-00074 | B78: North America | C78: US / Canada | D78: 45352 | E78: 21.3 | F78: 1767900 | G78: 9 | H78: 45627 | I78: 45717 | J78: FALSE | K78: 3.32
A79: NX-00075 | B79: North America | C79: US / Canada | D79: 45352 | E79: 10.3 | F79: 854900 | G79: 5 | H79: 45505 | I79: 45536 | J79: FALSE | K79: 0.65
A80: NX-00076 | B80: North America | C80: US / Canada | D80: 45352 | E80: 4.7 | F80: 390100 | G80: 8 | H80: 45597 | I80: 45597 | J80: FALSE | K80: 0.04
A81: NX-00077 | B81: North America | C81: US / Canada | D81: 45352 | E81: 16.2 | F81: 1344600 | G81: 11 | H81: 45689 | I81: 45689 | J81: FALSE | K81: 0.19
A82: NX-00078 | B82: North America | C82: US / Canada | D82: 45352 | E82: 5.9 | F82: 489700 | G82: 7 | H82: 45566 | I82: 45566 | J82: FALSE | K82: 0.06
... A98: NX-00094 | B98: EMEA | C98: Europe | D98: 45352 | E98: 13.1 | F98: 1152800 | G98: 7 | H98: 45566 | I98: 45597 | J98: FALSE | K98: 0.73
A99: NX-00095 | B99: EMEA | C99: MENA | D99: 45352 | E99: 36 | F99: 2916000 | G99: 9 | H99: 45627 | J99: TRUE | K99: 14.32
A100: NX-00096 | B100: EMEA | C100: MENA | D100: 45352 | E100: 8.8 | F100: 712800 | G100: 11 | H100: 45689 | I100: 46023 | J100: FALSE | K100: 11.3
A101: NX-00097 | B101: EMEA | C101: MENA | D101: 45352 | E101: 22.9 | F101: 1854900 | G101: 7 | H101: 45566 | I101: 45809 | J101: FALSE | K101: 8.28
A102: NX-00098 | B102: APAC | C102: India | D102: 45352 | E102: 20.2 | F102: 1434200 | G102: 7 | H102: 45566 | I102: 46054 | J102: FALSE | K102: 15.78
A103: NX-00099 | B103: APAC | C103: India | D103: 45352 | E103: 74.6 | F103: 5296600 | G103: 9 | H103: 45627 | I103: 45627 | J103: FALSE | K103: 0.01
A104: NX-00100 | B104: APAC | C104: India | D104: 45352 | E104: 8.6 | F104: 610600 | G104: 10 | H104: 45658 | I104: 45689 | J104: FALSE | K104: 0.58
A105: NX-00101 | B105: LATAM | C105: LATAM | D105: 45352 | E105: 3.1 | F105: 244900 | G105: 11 | H105: 45689 | I105: 45778 | J105: FALSE | K105: 2.9
A106: NX-00102 | B106: LATAM | C106: LATAM | D106: 45352 | E106: 51.5 | F106: 4068500 | G106: 11 | H106: 45689 | I106: 45689 | J106: FALSE | K106: 0.3
A107: NX-00103 | B107: LATAM | C107: LATAM | D107: 45352 | E107: 13.8 | F107: 1090200 | G107: 11 | H107: 45689 | I107: 45748 | J107: FALSE | K107: 2.44
A108: NX-00104 | B108: North America | C108: US / Canada | D108: 45383 | E108: 38.8 | F108: 3220400 | G108: 5 | H108: 45536 | I108: 45566 | J108: FALSE | K108: 1.27
A109: NX-00105 | B109: North America | C109: US / Canada | D109: 45383 | E109: 5.3 | F109: 439900 | G109: 5 | H109: 45536 | I109: 45566 | J109: FALSE | K109: 0.65
...

Sheet Engineered Orders
A1: Engineered fields
F3: =order_value x material rate -> #NAME? | J3: =whole months between expected and actual, a check on the supplied slip -> #NAME?
A4: order_id | B4: region | C4: market | D4: mw | E4: order_value | F4: material_committed | G4: expected_conversion | H4: actual_conversion | I4: slip_months | J4: slip_check_from_dates | K4: status | L4: material_at_risk
A5: ='Raw Orders'!A5 -> NX-00001 | B5: ='Raw Orders'!B5 -> North America | C5: ='Raw Orders'!C5 -> US / Canada | D5: ='Raw Orders'!E5 -> 31.5 | E5: ='Raw Orders'!F5 -> 2614500 | F5: ='Raw Orders'!F5*0.75 -> 1960875 | G5: ='Raw Orders'!H5 -> 45627 | H5: ='Raw Orders'!I5 -> 45717 | I5: ='Raw Orders'!K5 -> 2.72 | J5: =IF('Raw Orders'!J5,"",(YEAR('Raw Orders'!I5)-YEAR('Raw Orders'!H5))*12+MONTH('Raw Orders'!I5)-MONTH('Raw Orders'!H5)) -> 3 | K5: =IF('Raw Orders'!J5,"Cancelled",IF('Raw Orders'!K5>=2,"Slipped","On plan")) -> Slipped | L5: =IF(K5="On plan",0,F5) -> 1960875
A6: ='Raw Orders'!A6 -> NX-00002 | B6: ='Raw Orders'!B6 -> North America | C6: ='Raw Orders'!C6 -> US / Canada | D6: ='Raw Orders'!E6 -> 23.5 | E6: ='Raw Orders'!F6 -> 1950500 | F6: ='Raw Orders'!F6*0.75 -> 1462875 | G6: ='Raw Orders'!H6 -> 45505 | H6: ='Raw Orders'!I6 -> 45536 | I6: ='Raw Orders'!K6 -> 1.33 | J6: =IF('Raw Orders'!J6,"",(YEAR('Raw Orders'!I6)-YEAR('Raw Orders'!H6))*12+MONTH('Raw Orders'!I6)-MONTH('Raw Orders'!H6)) -> 1 | K6: =IF('Raw Orders'!J6,"Cancelled",IF('Raw Orders'!K6>=2,"Slipped","On plan")) -> On plan | L6: =IF(K6="On plan",0,F6) -> 0
A7: ='Raw Orders'!A7 -> NX-00003 | B7: ='Raw Orders'!B7 -> North America | C7: ='Raw Orders'!C7 -> US / Canada | D7: ='Raw Orders'!E7 -> 58.2 | E7: ='Raw Orders'!F7 -> 4830600 | F7: ='Raw Orders'!F7*0.75 -> 3622950 | G7: ='Raw Orders'!H7 -> 45627 | H7: ='Raw Orders'!I7 -> 45627 | I7: ='Raw Orders'!K7 -> 0.07 | J7: =IF('Raw Orders'!J7,"",(YEAR('Raw Orders'!I7)-YEAR('Raw Orders'!H7))*12+MONTH('Raw Orders'!I7)-MONTH('Raw Orders'!H7)) -> 0 | K7: =IF('Raw Orders'!J7,"Cancelled",IF('Raw Orders'!K7>=2,"Slipped","On plan")) -> On plan | L7: =IF(K7="On plan",0,F7) -> 0
A8: ='Raw Orders'!A8 -> NX-00004 | B8: ='Raw Orders'!B8 -> North America | C8: ='Raw Orders'!C8 -> US / Canada | D8: ='Raw Orders'!E8 -> 7 | E8: ='Raw Orders'!F8 -> 581000 | F8: ='Raw Orders'!F8*0.75 -> 435750 | G8: ='Raw Orders'!H8 -> 45505 | H8: ='Raw Orders'!I8 -> 45597 | I8: ='Raw Orders'!K8 -> 2.58 | J8: =IF('Raw Orders'!J8,"",(YEAR('Raw Orders'!I8)-YEAR('Raw Orders'!H8))*12+MONTH('Raw Orders'!I8)-MONTH('Raw Orders'!H8)) -> 3 | K8: =IF('Raw Orders'!J8,"Cancelled",IF('Raw Orders'!K8>=2,"Slipped","On plan")) -> Slipped | L8: =IF(K8="On plan",0,F8) -> 435750
A9: ='Raw Orders'!A9 -> NX-00005 | B9: ='Raw Orders'!B9 -> North America | C9: ='Raw Orders'!C9 -> US / Canada | D9: ='Raw Orders'!E9 -> 6 | E9: ='Raw Orders'!F9 -> 498000 | F9: ='Raw Orders'!F9*0.75 -> 373500 | G9: ='Raw Orders'!H9 -> 45444 | H9: ='Raw Orders'!I9 -> 45444 | I9: ='Raw Orders'!K9 -> 0 | J9: =IF('Raw Orders'!J9,"",(YEAR('Raw Orders'!I9)-YEAR('Raw Orders'!H9))*12+MONTH('Raw Orders'!I9)-MONTH('Raw Orders'!H9)) -> 0 | K9: =IF('Raw Orders'!J9,"Cancelled",IF('Raw Orders'!K9>=2,"Slipped","On plan")) -> On plan | L9: =IF(K9="On plan",0,F9) -> 0
A10: ='Raw Orders'!A10 -> NX-00006 | B10: ='Raw Orders'!B10 -> North America | C10: ='Raw Orders'!C10 -> US / Canada | D10: ='Raw Orders'!E10 -> 38.4 | E10: ='Raw Orders'!F10 -> 3187200 | F10: ='Raw Orders'!F10*0.75 -> 2390400 | G10: ='Raw Orders'!H10 -> 45627 | H10: ='Raw Orders'!I10 -> 45627 | I10: ='Raw Orders'!K10 -> 0 | J10: =IF('Raw Orders'!J10,"",(YEAR('Raw Orders'!I10)-YEAR('Raw Orders'!H10))*12+MONTH('Raw Orders'!I10)-MONTH('Raw Orders'!H10)) -> 0 | K10: =IF('Raw Orders'!J10,"Cancelled",IF('Raw Orders'!K10>=2,"Slipped","On plan")) -> On plan | L10: =IF(K10="On plan",0,F10) -> 0
A11: ='Raw Orders'!A11 -> NX-00007 | B11: ='Raw Orders'!B11 -> North America | C11: ='Raw Orders'!C11 -> US / Canada | D11: ='Raw Orders'!E11 -> 5.8 | E11: ='Raw Orders'!F11 -> 481400 | F11: ='Raw Orders'!F11*0.75 -> 361050 | G11: ='Raw Orders'!H11 -> 45505 | H11: ='Raw Orders'!I11 -> 45505 | I11: ='Raw Orders'!K11 -> 0 | J11: =IF('Raw Orders'!J11,"",(YEAR('Raw Orders'!I11)-YEAR('Raw Orders'!H11))*12+MONTH('Raw Orders'!I11)-MONTH('Raw Orders'!H11)) -> 0 | K11: =IF('Raw Orders'!J11,"Cancelled",IF('Raw Orders'!K11>=2,"Slipped","On plan")) -> On plan | L11: =IF(K11="On plan",0,F11) -> 0
A12: ='Raw Orders'!A12 -> NX-00008 | B12: ='Raw Orders'!B12 -> North America | C12: ='Raw Orders'!C12 -> US / Canada | D12: ='Raw Orders'!E12 -> 9.9 | E12: ='Raw Orders'!F12 -> 821700 | F12: ='Raw Orders'!F12*0.75 -> 616275 | G12: ='Raw Orders'!H12 -> 45444 | H12: ='Raw Orders'!I12 -> 45566 | I12: ='Raw Orders'!K12 -> 3.62 | J12: =IF('Raw Orders'!J12,"",(YEAR('Raw Orders'!I12)-YEAR('Raw Orders'!H12))*12+MONTH('Raw Orders'!I12)-MONTH('Raw Orders'!H12)) -> 4 | K12: =IF('Raw Orders'!J12,"Cancelled",IF('Raw Orders'!K12>=2,"Slipped","On plan")) -> Slipped | L12: =IF(K12="On plan",0,F12) -> 616275
A13: ='Raw Orders'!A13 -> NX-00009 | B13: ='Raw Orders'!B13 -> North America | C13: ='Raw Orders'!C13 -> US / Canada | D13: ='Raw Orders'!E13 -> 4.5 | E13: ='Raw Orders'!F13 -> 373500 | F13: ='Raw Orders'!F13*0.75 -> 280125 | G13: ='Raw Orders'!H13 -> 45627 | H13: ='Raw Orders'!I13 -> 45658 | I13: ='Raw Orders'!K13 -> 0.52 | J13: =IF('Raw Orders'!J13,"",(YEAR('Raw Orders'!I13)-YEAR('Raw Orders'!H13))*12+MONTH('Raw Orders'!I13)-MONTH('Raw Orders'!H13)) -> 1 | K13: =IF('Raw Orders'!J13,"Cancelled",IF('Raw Orders'!K13>=2,"Slipped","On plan")) -> On plan | L13: =IF(K13="On plan",0,F13) -> 0
A14: ='Raw Orders'!A14 -> NX-00010 | B14: ='Raw Orders'!B14 -> North America | C14: ='Raw Orders'!C14 -> US / Canada | D14: ='Raw Orders'!E14 -> 25.5 | E14: ='Raw Orders'!F14 -> 2116500 | F14: ='Raw Orders'!F14*0.75 -> 1587375 | G14: ='Raw Orders'!H14 -> 45505 | H14: ='Raw Orders'!I14 -> 45597 | I14: ='Raw Orders'!K14 -> 2.53 | J14: =IF('Raw Orders'!J14,"",(YEAR('Raw Orders'!I14)-YEAR('Raw Orders'!H14))*12+MONTH('Raw Orders'!I14)-MONTH('Raw Orders'!H14)) -> 3 | K14: =IF('Raw Orders'!J14,"Cancelled",IF('Raw Orders'!K14>=2,"Slipped","On plan")) -> Slipped | L14: =IF(K14="On plan",0,F14) -> 1587375
A15: ='Raw Orders'!A15 -> NX-00011 | B15: ='Raw Orders'!B15 -> North America | C15: ='Raw Orders'!C15 -> US / Canada | D15: ='Raw Orders'!E15 -> 14.3 | E15: ='Raw Orders'!F15 -> 1186900 | F15: ='Raw Orders'!F15*0.75 -> 890175 | G15: ='Raw Orders'!H15 -> 45627 | H15: ='Raw Orders'!I15 -> 45717 | I15: ='Raw Orders'!K15 -> 3.42 | J15: =IF('Raw Orders'!J15,"",(YEAR('Raw Orders'!I15)-YEAR('Raw Orders'!H15))*12+MONTH('Raw Orders'!I15)-MONTH('Raw Orders'!H15)) -> 3 | K15: =IF('Raw Orders'!J15,"Cancelled",IF('Raw Orders'!K15>=2,"Slipped","On plan")) -> Slipped | L15: =IF(K15="On plan",0,F15) -> 890175
A16: ='Raw Orders'!A16 -> NX-00012 | B16: ='Raw Orders'!B16 -> North America | C16: ='Raw Orders'!C16 -> US / Canada | D16: ='Raw Orders'!E16 -> 21.5 | E16: ='Raw Orders'!F16 -> 1784500 | F16: ='Raw Orders'!F16*0.75 -> 1338375 | G16: ='Raw Orders'!H16 -> 45566 | H16: ='Raw Orders'!I16 -> 45689 | I16: ='Raw Orders'!K16 -> 3.56 | J16: =IF('Raw Orders'!J16,"",(YEAR('Raw Orders'!I16)-YEAR('Raw Orders'!H16))*12+MONTH('Raw Orders'!I16)-MONTH('Raw Orders'!H16)) -> 4 | K16: =IF('Raw Orders'!J16,"Cancelled",IF('Raw Orders'!K16>=2,"Slipped","On plan")) -> Slipped | L16: =IF(K16="On plan",0,F16) -> 1338375
... A899: ='Raw Orders'!A899 -> NX-00895 | B899: ='Raw Orders'!B899 -> LATAM | C899: ='Raw Orders'!C899 -> LATAM | D899: ='Raw Orders'!E899 -> 6.9 | E899: ='Raw Orders'!F899 -> 545100 | F899: ='Raw Orders'!F899*0.75 -> 408825 | G899: ='Raw Orders'!H899 -> 46174 | H899: ='Raw Orders'!I899 -> 46174 | I899: ='Raw Orders'!K899 -> 0.21 | J899: =IF('Raw Orders'!J899,"",(YEAR('Raw Orders'!I899)-YEAR('Raw Orders'!H899))*12+MONTH('Raw Orders'!I899)-MONTH('Raw Orders'!H899)) -> 0 | K899: =IF('Raw Orders'!J899,"Cancelled",IF('Raw Orders'!K899>=2,"Slipped","On plan")) -> On plan | L899: =IF(K899="On plan",0,F899) -> 0

Sheet Monthly by Region
A1: Monthly aggregates by region
A4: region | B4: month | C4: orders booked | D4: MW booked | E4: value booked ($) | F4: value converted ($) | G4: backlog ($) | H4: book-to-bill | I4: material vs backlog ($)
A5: North America | B5: 45292 | C5: =COUNTIFS('Raw Orders'!$B$5:$B$899,$A5,'Raw Orders'!$D$5:$D$899,$B5) -> 12 | D5: =SUMIFS('Raw Orders'!$E$5:$E$899,'Raw Orders'!$B$5:$B$899,$A5,'Raw Orders'!$D$5:$D$899,$B5) -> 246.1 | E5: =SUMIFS('Raw Orders'!$F$5:$F$899,'Raw Orders'!$B$5:$B$899,$A5,'Raw Orders'!$D$5:$D$899,$B5) -> 20426300 | F5: =SUMIFS('Raw Orders'!$F$5:$F$899,'Raw Orders'!$B$5:$B$899,$A5,'Raw Orders'!$I$5:$I$899,$B5,'Raw Orders'!$J$5:$J$899,FALSE) -> 0 | G5: =SUMIFS('Raw Orders'!$F$5:$F$899,'Raw Orders'!$B$5:$B$899,$A5,'Raw Orders'!$D$5:$D$899,"<="&$B5)-SUMIFS('Raw Orders'!$F$5:$F$899,'Raw Orders'!$B$5:$B$899,$A5,'Raw Orders'!$I$5:$I$899,"<="&$B5,'Raw Orders'!$J$5:$J$899,FALSE) -> 20426300 | H5: =IF(F5=0,"",E5/F5) | I5: =G5*0.75 -> 15319725
A6: North America | B6: 45323 | C6: =COUNTIFS('Raw Orders'!$B$5:$B$899,$A6,'Raw Orders'!$D$5:$D$899,$B6) -> 18 | D6: =SUMIFS('Raw Orders'!$E$5:$E$899,'Raw Orders'!$B$5:$B$899,$A6,'Raw Orders'!$D$5:$D$899,$B6) -> 254.1 | E6: =SUMIFS('Raw Orders'!$F$5:$F$899,'Raw Orders'!$B$5:$B$899,$A6,'Raw Orders'!$D$5:$D$899,$B6) -> 21090300 | F6: =SUMIFS('Raw Orders'!$F$5:$F$899,'Raw Orders'!$B$5:$B$899,$A6,'Raw Orders'!$I$5:$I$899,$B6,'Raw Orders'!$J$5:$J$899,FALSE) -> 0 | G6: =SUMIFS('Raw Orders'!$F$5:$F$899,'Raw Orders'!$B$5:$B$899,$A6,'Raw Orders'!$D$5:$D$899,"<="&$B6)-SUMIFS('Raw Orders'!$F$5:$F$899,'Raw Orders'!$B$5:$B$899,$A6,'Raw Orders'!$I$5:$I$899,"<="&$B6,'Raw Orders'!$J$5:$J$899,FALSE) -> 41516600 | H6: =IF(F6=0,"",E6/F6) | I6: =G6*0.75 -> 31137450
A7: North America | B7: 45352 | C7: =COUNTIFS('Raw Orders'!$B$5:$B$899,$A7,'Raw Orders'!$D$5:$D$899,$B7) -> 30 | D7: =SUMIFS('Raw Orders'!$E$5:$E$899,'Raw Orders'!$B$5:$B$899,$A7,'Raw Orders'!$D$5:$D$899,$B7) -> 588 | E7: =SUMIFS('Raw Orders'!$F$5:$F$899,'Raw Orders'!$B$5:$B$899,$A7,'Raw Orders'!$D$5:$D$899,$B7) -> 48804000 | F7: =SUMIFS('Raw Orders'!$F$5:$F$899,'Raw Orders'!$B$5:$B$899,$A7,'Raw Orders'!$I$5:$I$899,$B7,'Raw Orders'!$J$5:$J$899,FALSE) -> 0 | G7: =SUMIFS('Raw Orders'!$F$5:$F$899,'Raw Orders'!$B$5:$B$899,$A7,'Raw Orders'!$D$5:$D$899,"<="&$B7)-SUMIFS('Raw Orders'!$F$5:$F$899,'Raw Orders'!$B$5:$B$899,$A7,'Raw Orders'!$I$5:$I$899,"<="&$B7,'Raw Orders'!$J$5:$J$899,FALSE) -> 90320600 | H7: =IF(F7=0,"",E7/F7) | I7: =G7*0.75 -> 67740450
A8: North America | B8: 45383 | C8: =COUNTIFS('Raw Orders'!$B$5:$B$899,$A8,'Raw Orders'!$D$5:$D$899,$B8) -> 27 | D8: =SUMIFS('Raw Orders'!$E$5:$E$899,'Raw Orders'!$B$5:$B$899,$A8,'Raw Orders'!$D$5:$D$899,$B8) -> 460.4 | E8: =SUMIFS('Raw Orders'!$F$5:$F$899,'Raw Orders'!$B$5:$B$899,$A8,'Raw Orders'!$D$5:$D$899,$B8) -> 38213200 | F8: =SUMIFS('Raw Orders'!$F$5:$F$899,'Raw Orders'!$B$5:$B$899,$A8,'Raw Orders'!$I$5:$I$899,$B8,'Raw Orders'!$J$5:$J$899,FALSE) -> 0 | G8: =SUMIFS('Raw Orders'!$F$5:$F$899,'Raw Orders'!$B$5:$B$899,$A8,'Raw Orders'!$D$5:$D$899,"<="&$B8)-SUMIFS('Raw Orders'!$F$5:$F$899,'Raw Orders'!$B$5:$B$899,$A8,'Raw Orders'!$I$5:$I$899,"<="&$B8,'Raw Orders'!$J$5:$J$899,FALSE) -> 128533800 | H8: =IF(F8=0,"",E8/F8) | I8: =G8*0.75 -> 96400350
A9: North America | B9: 45413 | C9: =COUNTIFS('Raw Orders'!$B$5:$B$899,$A9,'Raw Orders'!$D$5:$D$899,$B9) -> 25 | D9: =SUMIFS('Raw Orders'!$E$5:$E$899,'Raw Orders'!$B$5:$B$899,$A9,'Raw Orders'!$D$5:$D$899,$B9) -> 499 | E9: =SUMIFS('Raw Orders'!$F$5:$F$899,'Raw Orders'!$B$5:$B$899,$A9,'Raw Orders'!$D$5:$D$899,$B9) -> 41417000 | F9: =SUMIFS('Raw Orders'!$F$5:$F$899,'Raw Orders'!$B$5:$B$899,$A9,'Raw Orders'!$I$5:$I$899,$B9,'Raw Orders'!$J$5:$J$899,FALSE) -> 0 | G9: =SUMIFS('Raw Orders'!$F$5:$F$899,'Raw Orders'!$B$5:$B$899,$A9,'Raw Orders'!$D$5:$D$899,"<="&$B9)-SUMIFS('Raw Orders'!$F$5:$F$899,'Raw Orders'!$B$5:$B$899,$A9,'Raw Orders'!$I$5:$I$899,"<="&$B9,'Raw Orders'!$J$5:$J$899,FALSE) -> 169950800 | H9: =IF(F9=0,"",E9/F9) | I9: =G9*0.75 -> 127463100
A10: North America | B10: 45444 | C10: =COUNTIFS('Raw Orders'!$B$5:$B$899,$A10,'Raw Orders'!$D$5:$D$899,$B10) -> 35 | D10: =SUMIFS('Raw Orders'!$E$5:$E$899,'Raw Orders'!$B$5:$B$899,$A10,'Raw Orders'!$D$5:$D$899,$B10) -> 662.5 | E10: =SUMIFS('Raw Orders'!$F$5:$F$899,'Raw Orders'!$B$5:$B$899,$A10,'Raw Orders'!$D$5:$D$899,$B10) -> 54987500 | F10: =SUMIFS('Raw Orders'!$F$5:$F$899,'Raw Orders'!$B$5:$B$899,$A10,'Raw Orders'!$I$5:$I$899,$B10,'Raw Orders'!$J$5:$J$899,FALSE) -> 498000 | G10: =SUMIFS('Raw Orders'!$F$5:$F$899,'Raw Orders'!$B$5:$B$899,$A10,'Raw Orders'!$D$5:$D$899,"<="&$B10)-SUMIFS('Raw Orders'!$F$5:$F$899,'Raw Orders'!$B$5:$B$899,$A10,'Raw Orders'!$I$5:$I$899,"<="&$B10,'Raw Orders'!$J$5:$J$899,FALSE) -> 224440300 | H10: =IF(F10=0,"",E10/F10) -> 110.41667 | I10: =G10*0.75 -> 168330225
A11: North America | B11: 45474 | C11: =COUNTIFS('Raw Orders'!$B$5:$B$899,$A11,'Raw Orders'!$D$5:$D$899,$B11) -> 22 | D11: =SUMIFS('Raw Orders'!$E$5:$E$899,'Raw Orders'!$B$5:$B$899,$A11,'Raw Orders'!$D$5:$D$899,$B11) -> 464.3 | E11: =SUMIFS('Raw Orders'!$F$5:$F$899,'Raw Orders'!$B$5:$B$899,$A11,'Raw Orders'!$D$5:$D$899,$B11) -> 38536900 | F11: =SUMIFS('Raw Orders'!$F$5:$F$899,'Raw Orders'!$B$5:$B$899,$A11,'Raw Orders'!$I$5:$I$899,$B11,'Raw Orders'!$J$5:$J$899,FALSE) -> 730400 | G11: =SUMIFS('Raw Orders'!$F$5:$F$899,'Raw Orders'!$B$5:$B$899,$A11,'Raw Orders'!$D$5:$D$899,"<="&$B11)-SUMIFS('Raw Orders'!$F$5:$F$899,'Raw Orders'!$B$5:$B$899,$A11,'Raw Orders'!$I$5:$I$899,"<="&$B11,'Raw Orders'!$J$5:$J$899,FALSE) -> 262246800 | H11: =IF(F11=0,"",E11/F11) -> 52.761364 | I11: =G11*0.75 -> 196685100
A12: North America | B12: 45505 | C12: =COUNTIFS('Raw Orders'!$B$5:$B$899,$A12,'Raw Orders'!$D$5:$D$899,$B12) -> 16 | D12: =SUMIFS('Raw Orders'!$E$5:$E$899,'Raw Orders'!$B$5:$B$899,$A12,'Raw Orders'!$D$5:$D$899,$B12) -> 354.9 | E12: =SUMIFS('Raw Orders'!$F$5:$F$899,'Raw Orders'!$B$5:$B$899,$A12,'Raw Orders'!$D$5:$D$899,$B12) -> 29456700 | F12: =SUMIFS('Raw Orders'!$F$5:$F$899,'Raw Orders'!$B$5:$B$899,$A12,'Raw Orders'!$I$5:$I$899,$B12,'Raw Orders'!$J$5:$J$899,FALSE) -> 8466000 | G12: =SUMIFS('Raw Orders'!$F$5:$F$899,'Raw Orders'!$B$5:$B$899,$A12,'Raw Orders'!$D$5:$D$899,"<="&$B12)-SUMIFS('Raw Orders'!$F$5:$F$899,'Raw Orders'!$B$5:$B$899,$A12,'Raw Orders'!$I$5:$I$899,"<="&$B12,'Raw Orders'!$J$5:$J$899,FALSE) -> 283237500 | H12: =IF(F12=0,"",E12/F12) -> 3.4794118 | I12: =G12*0.75 -> 212428125
A13: North America | B13: 45536 | C13: =COUNTIFS('Raw Orders'!$B$5:$B$899,$A13,'Raw Orders'!$D$5:$D$899,$B13) -> 19 | D13: =SUMIFS('Raw Orders'!$E$5:$E$899,'Raw Orders'!$B$5:$B$899,$A13,'Raw Orders'!$D$5:$D$899,$B13) -> 298.6 | E13: =SUMIFS('Raw Orders'!$F$5:$F$899,'Raw Orders'!$B$5:$B$899,$A13,'Raw Orders'!$D$5:$D$899,$B13) -> 24783800 | F13: =SUMIFS('Raw Orders'!$F$5:$F$899,'Raw Orders'!$B$5:$B$899,$A13,'Raw Orders'!$I$5:$I$899,$B13,'Raw Orders'!$J$5:$J$899,FALSE) -> 13130600 | G13: =SUMIFS('Raw Orders'!$F$5:$F$899,'Raw Orders'!$B$5:$B$899,$A13,'Raw Orders'!$D$5:$D$899,"<="&$B13)-SUMIFS('Raw Orders'!$F$5:$F$899,'Raw Orders'!$B$5:$B$899,$A13,'Raw Orders'!$I$5:$I$899,"<="&$B13,'Raw Orders'!$J$5:$J$899,FALSE) -> 294890700 | H13: =IF(F13=0,"",E13/F13) -> 1.8874842 | I13: =G13*0.75 -> 221168025
A14: North America | B14: 45566 | C14: =COUNTIFS('Raw Orders'!$B$5:$B$899,$A14,'Raw Orders'!$D$5:$D$899,$B14) -> 23 | D14: =SUMIFS('Raw Orders'!$E$5:$E$899,'Raw Orders'!$B$5:$B$899,$A14,'Raw Orders'!$D$5:$D$899,$B14) -> 351.7 | E14: =SUMIFS('Raw Orders'!$F$5:$F$899,'Raw Orders'!$B$5:$B$899,$A14,'Raw Orders'!$D$5:$D$899,$B14) -> 29191100 | F14: =SUMIFS('Raw Orders'!$F$5:$F$899,'Raw Orders'!$B$5:$B$899,$A14,'Raw Orders'!$I$5:$I$899,$B14,'Raw Orders'!$J$5:$J$899,FALSE) -> 14085100 | G14: =SUMIFS('Raw Orders'!$F$5:$F$899,'Raw Orders'!$B$5:$B$899,$A14,'Raw Orders'!$D$5:$D$899,"<="&$B14)-SUMIFS('Raw Orders'!$F$5:$F$899,'Raw Orders'!$B$5:$B$899,$A14,'Raw Orders'!$I$5:$I$899,"<="&$B14,'Raw Orders'!$J$5:$J$899,FALSE) -> 309996700 | H14: =IF(F14=0,"",E14/F14) -> 2.0724808 | I14: =G14*0.75 -> 232497525
A15: North America | B15: 45597 | C15: =COUNTIFS('Raw Orders'!$B$5:$B$899,$A15,'Raw Orders'!$D$5:$D$899,$B15) -> 21 | D15: =SUMIFS('Raw Orders'!$E$5:$E$899,'Raw Orders'!$B$5:$B$899,$A15,'Raw Orders'!$D$5:$D$899,$B15) -> 431.8 | E15: =SUMIFS('Raw Orders'!$F$5:$F$899,'Raw Orders'!$B$5:$B$899,$A15,'Raw Orders'!$D$5:$D$899,$B15) -> 35839400 | F15: =SUMIFS('Raw Orders'!$F$5:$F$899,'Raw Orders'!$B$5:$B$899,$A15,'Raw Orders'!$I$5:$I$899,$B15,'Raw Orders'!$J$5:$J$899,FALSE) -> 16118600 | G15: =SUMIFS('Raw Orders'!$F$5:$F$899,'Raw Orders'!$B$5:$B$899,$A15,'Raw Orders'!$D$5:$D$899,"<="&$B15)-SUMIFS('Raw Orders'!$F$5:$F$899,'Raw Orders'!$B$5:$B$899,$A15,'Raw Orders'!$I$5:$I$899,"<="&$B15,'Raw Orders'!$J$5:$J$899,FALSE) -> 329717500 | H15: =IF(F15=0,"",E15/F15) -> 2.2234809 | I15: =G15*0.75 -> 247288125
A16: North America | B16: 45627 | C16: =COUNTIFS('Raw Orders'!$B$5:$B$899,$A16,'Raw Orders'!$D$5:$D$899,$B16) -> 24 | D16: =SUMIFS('Raw Orders'!$E$5:$E$899,'Raw Orders'!$B$5:$B$899,$A16,'Raw Orders'!$D$5:$D$899,$B16) -> 278.8 | E16: =SUMIFS('Raw Orders'!$F$5:$F$899,'Raw Orders'!$B$5:$B$899,$A16,'Raw Orders'!$D$5:$D$899,$B16) -> 23140400 | F16: =SUMIFS('Raw Orders'!$F$5:$F$899,'Raw Orders'!$B$5:$B$899,$A16,'Raw Orders'!$I$5:$I$899,$B16,'Raw Orders'!$J$5:$J$899,FALSE) -> 66424900 | G16: =SUMIFS('Raw Orders'!$F$5:$F$899,'Raw Orders'!$B$5:$B$899,$A16,'Raw Orders'!$D$5:$D$899,"<="&$B16)-SUMIFS('Raw Orders'!$F$5:$F$899,'Raw Orders'!$B$5:$B$899,$A16,'Raw Orders'!$I$5:$I$899,"<="&$B16,'Raw Orders'!$J$5:$J$899,FALSE) -> 286433000 | H16: =IF(F16=0,"",E16/F16) -> 0.34836936 | I16: =G16*0.75 -> 214824750
... A100: LATAM | B100: 45992 | C100: =COUNTIFS('Raw Orders'!$B$5:$B$899,$A100,'Raw Orders'!$D$5:$D$899,$B100) -> 2 | D100: =SUMIFS('Raw Orders'!$E$5:$E$899,'Raw Orders'!$B$5:$B$899,$A100,'Raw Orders'!$D$5:$D$899,$B100) -> 57.4 | E100: =SUMIFS('Raw Orders'!$F$5:$F$899,'Raw Orders'!$B$5:$B$899,$A100,'Raw Orders'!$D$5:$D$899,$B100) -> 4534600 | F100: =SUMIFS('Raw Orders'!$F$5:$F$899,'Raw Orders'!$B$5:$B$899,$A100,'Raw Orders'!$I$5:$I$899,$B100,'Raw Orders'!$J$5:$J$899,FALSE) -> 3302200 | G100: =SUMIFS('Raw Orders'!$F$5:$F$899,'Raw Orders'!$B$5:$B$899,$A100,'Raw Orders'!$D$5:$D$899,"<="&$B100)-SUMIFS('Raw Orders'!$F$5:$F$899,'Raw Orders'!$B$5:$B$899,$A100,'Raw Orders'!$I$5:$I$899,"<="&$B100,'Raw Orders'!$J$5:$J$899,FALSE) -> 32271500 | H100: =IF(F100=0,"",E100/F100) -> 1.3732057 | I100: =G100*0.75 -> 24203625

Sheet Slip by Market
A1: Schedule slip distribution by market
A4: market | B4: region | C4: orders | D4: P10 | E4: median | F4: P90 | G4: mean
A5: US / Canada | B5: North America | C5: =COUNTIFS('Raw Orders'!$C$5:$C$899,$A5,'Raw Orders'!$J$5:$J$899,FALSE) -> 608 | D5: {=PERCENTILE(IF(('Raw Orders'!$C$5:$C$899=$A5)*('Raw Orders'!$J$5:$J$899=FALSE),'Raw Orders'!$K$5:$K$899),0.1)} -> 0 | E5: {=PERCENTILE(IF(('Raw Orders'!$C$5:$C$899=$A5)*('Raw Orders'!$J$5:$J$899=FALSE),'Raw Orders'!$K$5:$K$899),0.5)} -> 0.1 | F5: {=PERCENTILE(IF(('Raw Orders'!$C$5:$C$899=$A5)*('Raw Orders'!$J$5:$J$899=FALSE),'Raw Orders'!$K$5:$K$899),0.9)} -> 1.759 | G5: =AVERAGEIFS('Raw Orders'!$K$5:$K$899,'Raw Orders'!$C$5:$C$899,$A5,'Raw Orders'!$J$5:$J$899,FALSE) -> 0.60981908
A6: Europe | B6: EMEA | C6: =COUNTIFS('Raw Orders'!$C$5:$C$899,$A6,'Raw Orders'!$J$5:$J$899,FALSE) -> 85 | D6: {=PERCENTILE(IF(('Raw Orders'!$C$5:$C$899=$A6)*('Raw Orders'!$J$5:$J$899=FALSE),'Raw Orders'!$K$5:$K$899),0.1)} -> 0.01 | E6: {=PERCENTILE(IF(('Raw Orders'!$C$5:$C$899=$A6)*('Raw Orders'!$J$5:$J$899=FALSE),'Raw Orders'!$K$5:$K$899),0.5)} -> 0.41 | F6: {=PERCENTILE(IF(('Raw Orders'!$C$5:$C$899=$A6)*('Raw Orders'!$J$5:$J$899=FALSE),'Raw Orders'!$K$5:$K$899),0.9)} -> 3.35 | G6: =AVERAGEIFS('Raw Orders'!$K$5:$K$899,'Raw Orders'!$C$5:$C$899,$A6,'Raw Orders'!$J$5:$J$899,FALSE) -> 1.2155294
A7: MENA | B7: EMEA | C7: =COUNTIFS('Raw Orders'!$C$5:$C$899,$A7,'Raw Orders'!$J$5:$J$899,FALSE) -> 52 | D7: {=PERCENTILE(IF(('Raw Orders'!$C$5:$C$899=$A7)*('Raw Orders'!$J$5:$J$899=FALSE),'Raw Orders'!$K$5:$K$899),0.1)} -> 0.033 | E7: {=PERCENTILE(IF(('Raw Orders'!$C$5:$C$899=$A7)*('Raw Orders'!$J$5:$J$899=FALSE),'Raw Orders'!$K$5:$K$899),0.5)} -> 0.62 | F7: {=PERCENTILE(IF(('Raw Orders'!$C$5:$C$899=$A7)*('Raw Orders'!$J$5:$J$899=FALSE),'Raw Orders'!$K$5:$K$899),0.9)} -> 7.4 | G7: =AVERAGEIFS('Raw Orders'!$K$5:$K$899,'Raw Orders'!$C$5:$C$899,$A7,'Raw Orders'!$J$5:$J$899,FALSE) -> 2.0863462
A8: Australia/SEA | B8: APAC | C8: =COUNTIFS('Raw Orders'!$C$5:$C$899,$A8,'Raw Orders'!$J$5:$J$899,FALSE) -> 26 | D8: {=PERCENTILE(IF(('Raw Orders'!$C$5:$C$899=$A8)*('Raw Orders'!$J$5:$J$899=FALSE),'Raw Orders'!$K$5:$K$899),0.1)} -> 0.045 | E8: {=PERCENTILE(IF(('Raw Orders'!$C$5:$C$899=$A8)*('Raw Orders'!$J$5:$J$899=FALSE),'Raw Orders'!$K$5:$K$899),0.5)} -> 0.865 | F8: {=PERCENTILE(IF(('Raw Orders'!$C$5:$C$899=$A8)*('Raw Orders'!$J$5:$J$899=FALSE),'Raw Orders'!$K$5:$K$899),0.9)} -> 4.075 | G8: =AVERAGEIFS('Raw Orders'!$K$5:$K$899,'Raw Orders'!$C$5:$C$899,$A8,'Raw Orders'!$J$5:$J$899,FALSE) -> 1.3846154
A9: India | B9: APAC | C9: =COUNTIFS('Raw Orders'!$C$5:$C$899,$A9,'Raw Orders'!$J$5:$J$899,FALSE) -> 47 | D9: {=PERCENTILE(IF(('Raw Orders'!$C$5:$C$899=$A9)*('Raw Orders'!$J$5:$J$899=FALSE),'Raw Orders'!$K$5:$K$899),0.1)} -> 0.382 | E9: {=PERCENTILE(IF(('Raw Orders'!$C$5:$C$899=$A9)*('Raw Orders'!$J$5:$J$899=FALSE),'Raw Orders'!$K$5:$K$899),0.5)} -> 3.03 | F9: {=PERCENTILE(IF(('Raw Orders'!$C$5:$C$899=$A9)*('Raw Orders'!$J$5:$J$899=FALSE),'Raw Orders'!$K$5:$K$899),0.9)} -> 9.824 | G9: =AVERAGEIFS('Raw Orders'!$K$5:$K$899,'Raw Orders'!$C$5:$C$899,$A9,'Raw Orders'!$J$5:$J$899,FALSE) -> 3.9829787
A10: LATAM | B10: LATAM | C10: =COUNTIFS('Raw Orders'!$C$5:$C$899,$A10,'Raw Orders'!$J$5:$J$899,FALSE) -> 57 | D10: {=PERCENTILE(IF(('Raw Orders'!$C$5:$C$899=$A10)*('Raw Orders'!$J$5:$J$899=FALSE),'Raw Orders'!$K$5:$K$899),0.1)} -> 0.032 | E10: {=PERCENTILE(IF(('Raw Orders'!$C$5:$C$899=$A10)*('Raw Orders'!$J$5:$J$899=FALSE),'Raw Orders'!$K$5:$K$899),0.5)} -> 0.6 | F10: {=PERCENTILE(IF(('Raw Orders'!$C$5:$C$899=$A10)*('Raw Orders'!$J$5:$J$899=FALSE),'Raw Orders'!$K$5:$K$899),0.9)} -> 3.564 | G10: =AVERAGEIFS('Raw Orders'!$K$5:$K$899,'Raw Orders'!$C$5:$C$899,$A10,'Raw Orders'!$J$5:$J$899,FALSE) -> 1.5901754
A13: The percentile columns are array formulas over the raw slip column, filtered to the market. Written as CSE arrays so they evaluate in any Excel version.

Sheet Region vs Market
A1: Market against regional blend
A4: region | B4: region P90 | C4: market | D4: market P90 | E4: gap vs region
A5: North America | B5: {=PERCENTILE(IF(('Raw Orders'!$B$5:$B$899=$A5)*('Raw Orders'!$J$5:$J$899=FALSE),'Raw Orders'!$K$5:$K$899),0.9)} -> 1.759 | C5: US / Canada | D5: {=PERCENTILE(IF(('Raw Orders'!$C$5:$C$899=$C5)*('Raw Orders'!$J$5:$J$899=FALSE),'Raw Orders'!$K$5:$K$899),0.9)} -> 1.759 | E5: =D5-B5 -> 0
A6: EMEA | B6: {=PERCENTILE(IF(('Raw Orders'!$B$5:$B$899=$A6)*('Raw Orders'!$J$5:$J$899=FALSE),'Raw Orders'!$K$5:$K$899),0.9)} -> 4.726 | C6: Europe | D6: {=PERCENTILE(IF(('Raw Orders'!$C$5:$C$899=$C6)*('Raw Orders'!$J$5:$J$899=FALSE),'Raw Orders'!$K$5:$K$899),0.9)} -> 3.35 | E6: =D6-B6 -> -1.376
A7: EMEA | B7: {=PERCENTILE(IF(('Raw Orders'!$B$5:$B$899=$A7)*('Raw Orders'!$J$5:$J$899=FALSE),'Raw Orders'!$K$5:$K$899),0.9)} -> 4.726 | C7: MENA | D7: {=PERCENTILE(IF(('Raw Orders'!$C$5:$C$899=$C7)*('Raw Orders'!$J$5:$J$899=FALSE),'Raw Orders'!$K$5:$K$899),0.9)} -> 7.4 | E7: =D7-B7 -> 2.674
A8: APAC | B8: {=PERCENTILE(IF(('Raw Orders'!$B$5:$B$899=$A8)*('Raw Orders'!$J$5:$J$899=FALSE),'Raw Orders'!$K$5:$K$899),0.9)} -> 6 | C8: Australia/SEA | D8: {=PERCENTILE(IF(('Raw Orders'!$C$5:$C$899=$C8)*('Raw Orders'!$J$5:$J$899=FALSE),'Raw Orders'!$K$5:$K$899),0.9)} -> 4.075 | E8: =D8-B8 -> -1.925
A9: APAC | B9: {=PERCENTILE(IF(('Raw Orders'!$B$5:$B$899=$A9)*('Raw Orders'!$J$5:$J$899=FALSE),'Raw Orders'!$K$5:$K$899),0.9)} -> 6 | C9: India | D9: {=PERCENTILE(IF(('Raw Orders'!$C$5:$C$899=$C9)*('Raw Orders'!$J$5:$J$899=FALSE),'Raw Orders'!$K$5:$K$899),0.9)} -> 9.824 | E9: =D9-B9 -> 3.824
A10: LATAM | B10: {=PERCENTILE(IF(('Raw Orders'!$B$5:$B$899=$A10)*('Raw Orders'!$J$5:$J$899=FALSE),'Raw Orders'!$K$5:$K$899),0.9)} -> 3.564 | C10: LATAM | D10: {=PERCENTILE(IF(('Raw Orders'!$C$5:$C$899=$C10)*('Raw Orders'!$J$5:$J$899=FALSE),'Raw Orders'!$K$5:$K$899),0.9)} -> 3.564 | E10: =D10-B10 -> 0

Sheet Lookback
A1: Conversion lookback
A4: region | B4: month | C4: expected MW | D4: actual MW | E4: realization | F4: bias MW | G4: cumulative bias MW
A5: North America | B5: 45292 | C5: =SUMIFS('Raw Orders'!$E$5:$E$899,'Raw Orders'!$B$5:$B$899,$A5,'Raw Orders'!$H$5:$H$899,$B5) -> 0 | D5: =SUMIFS('Raw Orders'!$E$5:$E$899,'Raw Orders'!$B$5:$B$899,$A5,'Raw Orders'!$I$5:$I$899,$B5,'Raw Orders'!$J$5:$J$899,FALSE) -> 0 | E5: =IF(C5=0,"",D5/C5) | F5: =D5-C5 -> 0 | G5: =SUM($F$5:$F5) -> 0
A6: North America | B6: 45323 | C6: =SUMIFS('Raw Orders'!$E$5:$E$899,'Raw Orders'!$B$5:$B$899,$A6,'Raw Orders'!$H$5:$H$899,$B6) -> 0 | D6: =SUMIFS('Raw Orders'!$E$5:$E$899,'Raw Orders'!$B$5:$B$899,$A6,'Raw Orders'!$I$5:$I$899,$B6,'Raw Orders'!$J$5:$J$899,FALSE) -> 0 | E6: =IF(C6=0,"",D6/C6) | F6: =D6-C6 -> 0 | G6: =SUM($F$5:$F6) -> 0
A7: North America | B7: 45352 | C7: =SUMIFS('Raw Orders'!$E$5:$E$899,'Raw Orders'!$B$5:$B$899,$A7,'Raw Orders'!$H$5:$H$899,$B7) -> 0 | D7: =SUMIFS('Raw Orders'!$E$5:$E$899,'Raw Orders'!$B$5:$B$899,$A7,'Raw Orders'!$I$5:$I$899,$B7,'Raw Orders'!$J$5:$J$899,FALSE) -> 0 | E7: =IF(C7=0,"",D7/C7) | F7: =D7-C7 -> 0 | G7: =SUM($F$5:$F7) -> 0
A8: North America | B8: 45383 | C8: =SUMIFS('Raw Orders'!$E$5:$E$899,'Raw Orders'!$B$5:$B$899,$A8,'Raw Orders'!$H$5:$H$899,$B8) -> 0 | D8: =SUMIFS('Raw Orders'!$E$5:$E$899,'Raw Orders'!$B$5:$B$899,$A8,'Raw Orders'!$I$5:$I$899,$B8,'Raw Orders'!$J$5:$J$899,FALSE) -> 0 | E8: =IF(C8=0,"",D8/C8) | F8: =D8-C8 -> 0 | G8: =SUM($F$5:$F8) -> 0
A9: North America | B9: 45413 | C9: =SUMIFS('Raw Orders'!$E$5:$E$899,'Raw Orders'!$B$5:$B$899,$A9,'Raw Orders'!$H$5:$H$899,$B9) -> 0 | D9: =SUMIFS('Raw Orders'!$E$5:$E$899,'Raw Orders'!$B$5:$B$899,$A9,'Raw Orders'!$I$5:$I$899,$B9,'Raw Orders'!$J$5:$J$899,FALSE) -> 0 | E9: =IF(C9=0,"",D9/C9) | F9: =D9-C9 -> 0 | G9: =SUM($F$5:$F9) -> 0
A10: North America | B10: 45444 | C10: =SUMIFS('Raw Orders'!$E$5:$E$899,'Raw Orders'!$B$5:$B$899,$A10,'Raw Orders'!$H$5:$H$899,$B10) -> 15.9 | D10: =SUMIFS('Raw Orders'!$E$5:$E$899,'Raw Orders'!$B$5:$B$899,$A10,'Raw Orders'!$I$5:$I$899,$B10,'Raw Orders'!$J$5:$J$899,FALSE) -> 6 | E10: =IF(C10=0,"",D10/C10) -> 0.37735849 | F10: =D10-C10 -> -9.9 | G10: =SUM($F$5:$F10) -> -9.9
A11: North America | B11: 45474 | C11: =SUMIFS('Raw Orders'!$E$5:$E$899,'Raw Orders'!$B$5:$B$899,$A11,'Raw Orders'!$H$5:$H$899,$B11) -> 14.2 | D11: =SUMIFS('Raw Orders'!$E$5:$E$899,'Raw Orders'!$B$5:$B$899,$A11,'Raw Orders'!$I$5:$I$899,$B11,'Raw Orders'!$J$5:$J$899,FALSE) -> 8.8 | E11: =IF(C11=0,"",D11/C11) -> 0.61971831 | F11: =D11-C11 -> -5.4 | G11: =SUM($F$5:$F11) -> -15.3
A12: North America | B12: 45505 | C12: =SUMIFS('Raw Orders'!$E$5:$E$899,'Raw Orders'!$B$5:$B$899,$A12,'Raw Orders'!$H$5:$H$899,$B12) -> 202.4 | D12: =SUMIFS('Raw Orders'!$E$5:$E$899,'Raw Orders'!$B$5:$B$899,$A12,'Raw Orders'!$I$5:$I$899,$B12,'Raw Orders'!$J$5:$J$899,FALSE) -> 102 | E12: =IF(C12=0,"",D12/C12) -> 0.50395257 | F12: =D12-C12 -> -100.4 | G12: =SUM($F$5:$F12) -> -115.7
A13: North America | B13: 45536 | C13: =SUMIFS('Raw Orders'!$E$5:$E$899,'Raw Orders'!$B$5:$B$899,$A13,'Raw Orders'!$H$5:$H$899,$B13) -> 142.4 | D13: =SUMIFS('Raw Orders'!$E$5:$E$899,'Raw Orders'!$B$5:$B$899,$A13,'Raw Orders'!$I$5:$I$899,$B13,'Raw Orders'!$J$5:$J$899,FALSE) -> 158.2 | E13: =IF(C13=0,"",D13/C13) -> 1.1109551 | F13: =D13-C13 -> 15.8 | G13: =SUM($F$5:$F13) -> -99.9
A14: North America | B14: 45566 | C14: =SUMIFS('Raw Orders'!$E$5:$E$899,'Raw Orders'!$B$5:$B$899,$A14,'Raw Orders'!$H$5:$H$899,$B14) -> 232.6 | D14: =SUMIFS('Raw Orders'!$E$5:$E$899,'Raw Orders'!$B$5:$B$899,$A14,'Raw Orders'!$I$5:$I$899,$B14,'Raw Orders'!$J$5:$J$899,FALSE) -> 169.7 | E14: =IF(C14=0,"",D14/C14) -> 0.72957868 | F14: =D14-C14 -> -62.9 | G14: =SUM($F$5:$F14) -> -162.8
A15: North America | B15: 45597 | C15: =SUMIFS('Raw Orders'!$E$5:$E$899,'Raw Orders'!$B$5:$B$899,$A15,'Raw Orders'!$H$5:$H$899,$B15) -> 294.1 | D15: =SUMIFS('Raw Orders'!$E$5:$E$899,'Raw Orders'!$B$5:$B$899,$A15,'Raw Orders'!$I$5:$I$899,$B15,'Raw Orders'!$J$5:$J$899,FALSE) -> 194.2 | E15: =IF(C15=0,"",D15/C15) -> 0.66031962 | F15: =D15-C15 -> -99.9 | G15: =SUM($F$5:$F15) -> -262.7
A16: North America | B16: 45627 | C16: =SUMIFS('Raw Orders'!$E$5:$E$899,'Raw Orders'!$B$5:$B$899,$A16,'Raw Orders'!$H$5:$H$899,$B16) -> 846.4 | D16: =SUMIFS('Raw Orders'!$E$5:$E$899,'Raw Orders'!$B$5:$B$899,$A16,'Raw Orders'!$I$5:$I$899,$B16,'Raw Orders'!$J$5:$J$899,FALSE) -> 800.3 | E16: =IF(C16=0,"",D16/C16) -> 0.94553403 | F16: =D16-C16 -> -46.1 | G16: =SUM($F$5:$F16) -> -308.8
... A28: North America | B28: 45992 | C28: =SUMIFS('Raw Orders'!$E$5:$E$899,'Raw Orders'!$B$5:$B$899,$A28,'Raw Orders'!$H$5:$H$899,$B28) -> 479.8 | D28: =SUMIFS('Raw Orders'!$E$5:$E$899,'Raw Orders'!$B$5:$B$899,$A28,'Raw Orders'!$I$5:$I$899,$B28,'Raw Orders'!$J$5:$J$899,FALSE) -> 527 | E28: =IF(C28=0,"",D28/C28) -> 1.0983743 | F28: =D28-C28 -> 47.2 | G28: =SUM($F$5:$F28) -> -232.9
A29: EMEA | B29: 45292 | C29: =SUMIFS('Raw Orders'!$E$5:$E$899,'Raw Orders'!$B$5:$B$899,$A29,'Raw Orders'!$H$5:$H$899,$B29) -> 0 | D29: =SUMIFS('Raw Orders'!$E$5:$E$899,'Raw Orders'!$B$5:$B$899,$A29,'Raw Orders'!$I$5:$I$899,$B29,'Raw Orders'!$J$5:$J$899,FALSE) -> 0 | E29: =IF(C29=0,"",D29/C29) | F29: =D29-C29 -> 0 | G29: =SUM($F$29:$F29) -> 0
A30: EMEA | B30: 45323 | C30: =SUMIFS('Raw Orders'!$E$5:$E$899,'Raw Orders'!$B$5:$B$899,$A30,'Raw Orders'!$H$5:$H$899,$B30) -> 0 | D30: =SUMIFS('Raw Orders'!$E$5:$E$899,'Raw Orders'!$B$5:$B$899,$A30,'Raw Orders'!$I$5:$I$899,$B30,'Raw Orders'!$J$5:$J$899,FALSE) -> 0 | E30: =IF(C30=0,"",D30/C30) | F30: =D30-C30 -> 0 | G30: =SUM($F$29:$F30) -> 0
A31: EMEA | B31: 45352 | C31: =SUMIFS('Raw Orders'!$E$5:$E$899,'Raw Orders'!$B$5:$B$899,$A31,'Raw Orders'!$H$5:$H$899,$B31) -> 0 | D31: =SUMIFS('Raw Orders'!$E$5:$E$899,'Raw Orders'!$B$5:$B$899,$A31,'Raw Orders'!$I$5:$I$899,$B31,'Raw Orders'!$J$5:$J$899,FALSE) -> 0 | E31: =IF(C31=0,"",D31/C31) | F31: =D31-C31 -> 0 | G31: =SUM($F$29:$F31) -> 0
A32: EMEA | B32: 45383 | C32: =SUMIFS('Raw Orders'!$E$5:$E$899,'Raw Orders'!$B$5:$B$899,$A32,'Raw Orders'!$H$5:$H$899,$B32) -> 0 | D32: =SUMIFS('Raw Orders'!$E$5:$E$899,'Raw Orders'!$B$5:$B$899,$A32,'Raw Orders'!$I$5:$I$899,$B32,'Raw Orders'!$J$5:$J$899,FALSE) -> 0 | E32: =IF(C32=0,"",D32/C32) | F32: =D32-C32 -> 0 | G32: =SUM($F$29:$F32) -> 0
A33: EMEA | B33: 45413 | C33: =SUMIFS('Raw Orders'!$E$5:$E$899,'Raw Orders'!$B$5:$B$899,$A33,'Raw Orders'!$H$5:$H$899,$B33) -> 0 | D33: =SUMIFS('Raw Orders'!$E$5:$E$899,'Raw Orders'!$B$5:$B$899,$A33,'Raw Orders'!$I$5:$I$899,$B33,'Raw Orders'!$J$5:$J$899,FALSE) -> 0 | E33: =IF(C33=0,"",D33/C33) | F33: =D33-C33 -> 0 | G33: =SUM($F$29:$F33) -> 0
A34: EMEA | B34: 45444 | C34: =SUMIFS('Raw Orders'!$E$5:$E$899,'Raw Orders'!$B$5:$B$899,$A34,'Raw Orders'!$H$5:$H$899,$B34) -> 53.8 | D34: =SUMIFS('Raw Orders'!$E$5:$E$899,'Raw Orders'!$B$5:$B$899,$A34,'Raw Orders'!$I$5:$I$899,$B34,'Raw Orders'!$J$5:$J$899,FALSE) -> 0 | E34: =IF(C34=0,"",D34/C34) -> 0 | F34: =D34-C34 -> -53.8 | G34: =SUM($F$29:$F34) -> -53.8
A35: EMEA | B35: 45474 | C35: =SUMIFS('Raw Orders'!$E$5:$E$899,'Raw Orders'!$B$5:$B$899,$A35,'Raw Orders'!$H$5:$H$899,$B35) -> 71.9 | D35: =SUMIFS('Raw Orders'!$E$5:$E$899,'Raw Orders'!$B$5:$B$899,$A35,'Raw Orders'!$I$5:$I$899,$B35,'Raw Orders'!$J$5:$J$899,FALSE) -> 0 | E35: =IF(C35=0,"",D35/C35) -> 0 | F35: =D35-C35 -> -71.9 | G35: =SUM($F$29:$F35) -> -125.7
A36: EMEA | B36: 45505 | C36: =SUMIFS('Raw Orders'!$E$5:$E$899,'Raw Orders'!$B$5:$B$899,$A36,'Raw Orders'!$H$5:$H$899,$B36) -> 30.6 | D36: =SUMIFS('Raw Orders'!$E$5:$E$899,'Raw Orders'!$B$5:$B$899,$A36,'Raw Orders'!$I$5:$I$899,$B36,'Raw Orders'!$J$5:$J$899,FALSE) -> 30.6 | E36: =IF(C36=0,"",D36/C36) -> 1 | F36: =D36-C36 -> 0 | G36: =SUM($F$29:$F36) -> -125.7
A37: EMEA | B37: 45536 | C37: =SUMIFS('Raw Orders'!$E$5:$E$899,'Raw Orders'!$B$5:$B$899,$A37,'Raw Orders'!$H$5:$H$899,$B37) -> 9.8 | D37: =SUMIFS('Raw Orders'!$E$5:$E$899,'Raw Orders'!$B$5:$B$899,$A37,'Raw Orders'!$I$5:$I$899,$B37,'Raw Orders'!$J$5:$J$899,FALSE) -> 34.6 | E37: =IF(C37=0,"",D37/C37) -> 3.5306122 | F37: =D37-C37 -> 24.8 | G37: =SUM($F$29:$F37) -> -100.9
A38: EMEA | B38: 45566 | C38: =SUMIFS('Raw Orders'!$E$5:$E$899,'Raw Orders'!$B$5:$B$899,$A38,'Raw Orders'!$H$5:$H$899,$B38) -> 99.3 | D38: =SUMIFS('Raw Orders'!$E$5:$E$899,'Raw Orders'!$B$5:$B$899,$A38,'Raw Orders'!$I$5:$I$899,$B38,'Raw Orders'!$J$5:$J$899,FALSE) -> 43.3 | E38: =IF(C38=0,"",D38/C38) -> 0.43605237 | F38: =D38-C38 -> -56 | G38: =SUM($F$29:$F38) -> -156.9
A39: EMEA | B39: 45597 | C39: =SUMIFS('Raw Orders'!$E$5:$E$899,'Raw Orders'!$B$5:$B$899,$A39,'Raw Orders'!$H$5:$H$899,$B39) -> 121.8 | D39: =SUMIFS('Raw Orders'!$E$5:$E$899,'Raw Orders'!$B$5:$B$899,$A39,'Raw Orders'!$I$5:$I$899,$B39,'Raw Orders'!$J$5:$J$899,FALSE) -> 42.2 | E39: =IF(C39=0,"",D39/C39) -> 0.34646962 | F39: =D39-C39 -> -79.6 | G39: =SUM($F$29:$F39) -> -236.5
A40: EMEA | B40: 45627 | C40: =SUMIFS('Raw Orders'!$E$5:$E$899,'Raw Orders'!$B$5:$B$899,$A40,'Raw Orders'!$H$5:$H$899,$B40) -> 84.9 | D40: =SUMIFS('Raw Orders'!$E$5:$E$899,'Raw Orders'!$B$5:$B$899,$A40,'Raw Orders'!$I$5:$I$899,$B40,'Raw Orders'!$J$5:$J$899,FALSE) -> 97 | E40: =IF(C40=0,"",D40/C40) -> 1.1425206 | F40: =D40-C40 -> 12.1 | G40: =SUM($F$29:$F40) -> -224.4
... A52: EMEA | B52: 45992 | C52: =SUMIFS('Raw Orders'!$E$5:$E$899,'Raw Orders'!$B$5:$B$899,$A52,'Raw Orders'!$H$5:$H$899,$B52) -> 142.5 | D52: =SUMIFS('Raw Orders'!$E$5:$E$899,'Raw Orders'!$B$5:$B$899,$A52,'Raw Orders'!$I$5:$I$899,$B52,'Raw Orders'!$J$5:$J$899,FALSE) -> 160.9 | E52: =IF(C52=0,"",D52/C52) -> 1.1291228 | F52: =D52-C52 -> 18.4 | G52: =SUM($F$29:$F52) -> -138.7
A53: APAC | B53: 45292 | C53: =SUMIFS('Raw Orders'!$E$5:$E$899,'Raw Orders'!$B$5:$B$899,$A53,'Raw Orders'!$H$5:$H$899,$B53) -> 0 | D53: =SUMIFS('Raw Orders'!$E$5:$E$899,'Raw Orders'!$B$5:$B$899,$A53,'Raw Orders'!$I$5:$I$899,$B53,'Raw Orders'!$J$5:$J$899,FALSE) -> 0 | E53: =IF(C53=0,"",D53/C53) | F53: =D53-C53 -> 0 | G53: =SUM($F$53:$F53) -> 0
A54: APAC | B54: 45323 | C54: =SUMIFS('Raw Orders'!$E$5:$E$899,'Raw Orders'!$B$5:$B$899,$A54,'Raw Orders'!$H$5:$H$899,$B54) -> 0 | D54: =SUMIFS('Raw Orders'!$E$5:$E$899,'Raw Orders'!$B$5:$B$899,$A54,'Raw Orders'!$I$5:$I$899,$B54,'Raw Orders'!$J$5:$J$899,FALSE) -> 0 | E54: =IF(C54=0,"",D54/C54) | F54: =D54-C54 -> 0 | G54: =SUM($F$53:$F54) -> 0
A55: APAC | B55: 45352 | C55: =SUMIFS('Raw Orders'!$E$5:$E$899,'Raw Orders'!$B$5:$B$899,$A55,'Raw Orders'!$H$5:$H$899,$B55) -> 0 | D55: =SUMIFS('Raw Orders'!$E$5:$E$899,'Raw Orders'!$B$5:$B$899,$A55,'Raw Orders'!$I$5:$I$899,$B55,'Raw Orders'!$J$5:$J$899,FALSE) -> 0 | E55: =IF(C55=0,"",D55/C55) | F55: =D55-C55 -> 0 | G55: =SUM($F$53:$F55) -> 0
A56: APAC | B56: 45383 | C56: =SUMIFS('Raw Orders'!$E$5:$E$899,'Raw Orders'!$B$5:$B$899,$A56,'Raw Orders'!$H$5:$H$899,$B56) -> 0 | D56: =SUMIFS('Raw Orders'!$E$5:$E$899,'Raw Orders'!$B$5:$B$899,$A56,'Raw Orders'!$I$5:$I$899,$B56,'Raw Orders'!$J$5:$J$899,FALSE) -> 0 | E56: =IF(C56=0,"",D56/C56) | F56: =D56-C56 -> 0 | G56: =SUM($F$53:$F56) -> 0
A57: APAC | B57: 45413 | C57: =SUMIFS('Raw Orders'!$E$5:$E$899,'Raw Orders'!$B$5:$B$899,$A57,'Raw Orders'!$H$5:$H$899,$B57) -> 0 | D57: =SUMIFS('Raw Orders'!$E$5:$E$899,'Raw Orders'!$B$5:$B$899,$A57,'Raw Orders'!$I$5:$I$899,$B57,'Raw Orders'!$J$5:$J$899,FALSE) -> 0 | E57: =IF(C57=0,"",D57/C57) | F57: =D57-C57 -> 0 | G57: =SUM($F$53:$F57) -> 0
A58: APAC | B58: 45444 | C58: =SUMIFS('Raw Orders'!$E$5:$E$899,'Raw Orders'!$B$5:$B$899,$A58,'Raw Orders'!$H$5:$H$899,$B58) -> 0 | D58: =SUMIFS('Raw Orders'!$E$5:$E$899,'Raw Orders'!$B$5:$B$899,$A58,'Raw Orders'!$I$5:$I$899,$B58,'Raw Orders'!$J$5:$J$899,FALSE) -> 0 | E58: =IF(C58=0,"",D58/C58) | F58: =D58-C58 -> 0 | G58: =SUM($F$53:$F58) -> 0
A59: APAC | B59: 45474 | C59: =SUMIFS('Raw Orders'!$E$5:$E$899,'Raw Orders'!$B$5:$B$899,$A59,'Raw Orders'!$H$5:$H$899,$B59) -> 33.8 | D59: =SUMIFS('Raw Orders'!$E$5:$E$899,'Raw Orders'!$B$5:$B$899,$A59,'Raw Orders'!$I$5:$I$899,$B59,'Raw Orders'!$J$5:$J$899,FALSE) -> 0 | E59: =IF(C59=0,"",D59/C59) -> 0 | F59: =D59-C59 -> -33.8 | G59: =SUM($F$53:$F59) -> -33.8
A60: APAC | B60: 45505 | C60: =SUMIFS('Raw Orders'!$E$5:$E$899,'Raw Orders'!$B$5:$B$899,$A60,'Raw Orders'!$H$5:$H$899,$B60) -> 0 | D60: =SUMIFS('Raw Orders'!$E$5:$E$899,'Raw Orders'!$B$5:$B$899,$A60,'Raw Orders'!$I$5:$I$899,$B60,'Raw Orders'!$J$5:$J$899,FALSE) -> 0 | E60: =IF(C60=0,"",D60/C60) | F60: =D60-C60 -> 0 | G60: =SUM($F$53:$F60) -> -33.8
A61: APAC | B61: 45536 | C61: =SUMIFS('Raw Orders'!$E$5:$E$899,'Raw Orders'!$B$5:$B$899,$A61,'Raw Orders'!$H$5:$H$899,$B61) -> 65.7 | D61: =SUMIFS('Raw Orders'!$E$5:$E$899,'Raw Orders'!$B$5:$B$899,$A61,'Raw Orders'!$I$5:$I$899,$B61,'Raw Orders'!$J$5:$J$899,FALSE) -> 19.3 | E61: =IF(C61=0,"",D61/C61) -> 0.29375951 | F61: =D61-C61 -> -46.4 | G61: =SUM($F$53:$F61) -> -80.2
A62: APAC | B62: 45566 | C62: =SUMIFS('Raw Orders'!$E$5:$E$899,'Raw Orders'!$B$5:$B$899,$A62,'Raw Orders'!$H$5:$H$899,$B62) -> 45.7 | D62: =SUMIFS('Raw Orders'!$E$5:$E$899,'Raw Orders'!$B$5:$B$899,$A62,'Raw Orders'!$I$5:$I$899,$B62,'Raw Orders'!$J$5:$J$899,FALSE) -> 40.2 | E62: =IF(C62=0,"",D62/C62) -> 0.87964989 | F62: =D62-C62 -> -5.5 | G62: =SUM($F$53:$F62) -> -85.7
A63: APAC | B63: 45597 | C63: =SUMIFS('Raw Orders'!$E$5:$E$899,'Raw Orders'!$B$5:$B$899,$A63,'Raw Orders'!$H$5:$H$899,$B63) -> 52.2 | D63: =SUMIFS('Raw Orders'!$E$5:$E$899,'Raw Orders'!$B$5:$B$899,$A63,'Raw Orders'!$I$5:$I$899,$B63,'Raw Orders'!$J$5:$J$899,FALSE) -> 33.4 | E63: =IF(C63=0,"",D63/C63) -> 0.63984674 | F63: =D63-C63 -> -18.8 | G63: =SUM($F$53:$F63) -> -104.5
A64: APAC | B64: 45627 | C64: =SUMIFS('Raw Orders'!$E$5:$E$899,'Raw Orders'!$B$5:$B$899,$A64,'Raw Orders'!$H$5:$H$899,$B64) -> 85.4 | D64: =SUMIFS('Raw Orders'!$E$5:$E$899,'Raw Orders'!$B$5:$B$899,$A64,'Raw Orders'!$I$5:$I$899,$B64,'Raw Orders'!$J$5:$J$899,FALSE) -> 107.6 | E64: =IF(C64=0,"",D64/C64) -> 1.2599532 | F64: =D64-C64 -> 22.2 | G64: =SUM($F$53:$F64) -> -82.3
...

Sheet Commitment
A1: Material committed against backlog
A4: region | B4: closing backlog ($) | C4: at 100% | D4: at 95% | E4: at 90% | F4: at 85% | G4: at 80% | H4: at 75% | I4: at 70% | J4: exposure 100% vs 70%
A5: North America | B5: =SUMIFS('Raw Orders'!$F$5:$F$899,'Raw Orders'!$B$5:$B$899,$A5,'Raw Orders'!$D$5:$D$899,"<="&DATE(2025,12,1))-SUMIFS('Raw Orders'!$F$5:$F$899,'Raw Orders'!$B$5:$B$899,$A5,'Raw Orders'!$I$5:$I$899,"<="&DATE(2025,12,1),'Raw Orders'!$J$5:$J$899,FALSE) -> 392764300 | C5: =$B5*0.75*1 -> 294573225 | D5: =$B5*0.75*0.95 -> 2.7984456e+08 | E5: =$B5*0.75*0.9 -> 2.651159e+08 | F5: =$B5*0.75*0.85 -> 2.5038724e+08 | G5: =$B5*0.75*0.8 -> 235658580 | H5: =$B5*0.75*0.75 -> 2.2092992e+08 | I5: =$B5*0.75*0.7 -> 2.0620126e+08 | J5: =C5-I5 -> 88371968
A6: EMEA | B6: =SUMIFS('Raw Orders'!$F$5:$F$899,'Raw Orders'!$B$5:$B$899,$A6,'Raw Orders'!$D$5:$D$899,"<="&DATE(2025,12,1))-SUMIFS('Raw Orders'!$F$5:$F$899,'Raw Orders'!$B$5:$B$899,$A6,'Raw Orders'!$I$5:$I$899,"<="&DATE(2025,12,1),'Raw Orders'!$J$5:$J$899,FALSE) -> 102663100 | C6: =$B6*0.75*1 -> 76997325 | D6: =$B6*0.75*0.95 -> 73147459 | E6: =$B6*0.75*0.9 -> 69297592 | F6: =$B6*0.75*0.85 -> 65447726 | G6: =$B6*0.75*0.8 -> 61597860 | H6: =$B6*0.75*0.75 -> 57747994 | I6: =$B6*0.75*0.7 -> 53898128 | J6: =C6-I6 -> 23099198
A7: APAC | B7: =SUMIFS('Raw Orders'!$F$5:$F$899,'Raw Orders'!$B$5:$B$899,$A7,'Raw Orders'!$D$5:$D$899,"<="&DATE(2025,12,1))-SUMIFS('Raw Orders'!$F$5:$F$899,'Raw Orders'!$B$5:$B$899,$A7,'Raw Orders'!$I$5:$I$899,"<="&DATE(2025,12,1),'Raw Orders'!$J$5:$J$899,FALSE) -> 53816600 | C7: =$B7*0.75*1 -> 40362450 | D7: =$B7*0.75*0.95 -> 38344328 | E7: =$B7*0.75*0.9 -> 36326205 | F7: =$B7*0.75*0.85 -> 34308082 | G7: =$B7*0.75*0.8 -> 32289960 | H7: =$B7*0.75*0.75 -> 30271838 | I7: =$B7*0.75*0.7 -> 28253715 | J7: =C7-I7 -> 12108735
A8: LATAM | B8: =SUMIFS('Raw Orders'!$F$5:$F$899,'Raw Orders'!$B$5:$B$899,$A8,'Raw Orders'!$D$5:$D$899,"<="&DATE(2025,12,1))-SUMIFS('Raw Orders'!$F$5:$F$899,'Raw Orders'!$B$5:$B$899,$A8,'Raw Orders'!$I$5:$I$899,"<="&DATE(2025,12,1),'Raw Orders'!$J$5:$J$899,FALSE) -> 32271500 | C8: =$B8*0.75*1 -> 24203625 | D8: =$B8*0.75*0.95 -> 22993444 | E8: =$B8*0.75*0.9 -> 21783262 | F8: =$B8*0.75*0.85 -> 20573081 | G8: =$B8*0.75*0.8 -> 19362900 | H8: =$B8*0.75*0.75 -> 18152719 | I8: =$B8*0.75*0.7 -> 16942538 | J8: =C8-I8 -> 7261087.5
A9: Total | B9: =SUM(B5:B8) -> 581515500 | C9: =SUM(C5:C8) -> 436136625 | D9: =SUM(D5:D8) -> 4.1432979e+08 | E9: =SUM(E5:E8) -> 3.9252296e+08 | F9: =SUM(F5:F8) -> 3.7071613e+08 | G9: =SUM(G5:G8) -> 348909300 | H9: =SUM(H5:H8) -> 3.2710247e+08 | I9: =SUM(I5:I8) -> 3.0529564e+08 | J9: =SUM(J5:J8) -> 1.3084099e+08

Sheet MC Forward
A1: Forward material requirement
A4: month | B4: already booked ($) | C4: not yet booked ($) | D4: expected total ($) | E4: low (P10) | F4: high (P90) | G4: spread | H4: calibrated low | I4: calibrated high | J4: firm share
A5: 46023 | B5: 49591088 | C5: 0 | D5: 49591088 | E5: 40679235 | F5: 56987692 | G5: =F5-E5 -> 16308458 | H5: =D5-'MC Calibration'!$C$59*G5 -> 37609442 | I5: =D5+'MC Calibration'!$C$59*G5 -> 61572733 | J5: =IF(D5=0,"",B5/D5) -> 1
A6: 46054 | B6: 44885738 | C6: 0 | D6: 44885738 | E6: 36452618 | F6: 53786408 | G6: =F6-E6 -> 17333790 | H6: =D6-'MC Calibration'!$C$59*G6 -> 32150791 | I6: =D6+'MC Calibration'!$C$59*G6 -> 57620684 | J6: =IF(D6=0,"",B6/D6) -> 1
A7: 46082 | B7: 44395312 | C7: 0 | D7: 44395312 | E7: 36327510 | F7: 53136008 | G7: =F7-E7 -> 16808498 | H7: =D7-'MC Calibration'!$C$59*G7 -> 32046293 | I7: =D7+'MC Calibration'!$C$59*G7 -> 56744332 | J7: =IF(D7=0,"",B7/D7) -> 1
A8: 46113 | B8: 42483750 | C8: 0 | D8: 42483750 | E8: 34615868 | F8: 51454995 | G8: =F8-E8 -> 16839128 | H8: =D8-'MC Calibration'!$C$59*G8 -> 30112227 | I8: =D8+'MC Calibration'!$C$59*G8 -> 54855273 | J8: =IF(D8=0,"",B8/D8) -> 1
A9: 46143 | B9: 43696425 | C9: 0 | D9: 43696425 | E9: 36090668 | F9: 51870308 | G9: =F9-E9 -> 15779640 | H9: =D9-'MC Calibration'!$C$59*G9 -> 32103296 | I9: =D9+'MC Calibration'!$C$59*G9 -> 55289554 | J9: =IF(D9=0,"",B9/D9) -> 1
A10: 46174 | B10: 33939300 | C10: 4646400 | D10: 38992950 | E10: 30726855 | F10: 47797208 | G10: =F10-E10 -> 17070352 | H10: =D10-'MC Calibration'!$C$59*G10 -> 26451548 | I10: =D10+'MC Calibration'!$C$59*G10 -> 51534352 | J10: =IF(D10=0,"",B10/D10) -> 0.8703958
A11: 46204 | B11: 31826588 | C11: 9875850 | D11: 42376162 | E11: 33818168 | F11: 52233172 | G11: =F11-E11 -> 18415005 | H11: =D11-'MC Calibration'!$C$59*G11 -> 28846859 | I11: =D11+'MC Calibration'!$C$59*G11 -> 55905466 | J11: =IF(D11=0,"",B11/D11) -> 0.75104931
A12: 46235 | B12: 28579650 | C12: 15342600 | D12: 44110500 | E12: 34724355 | F12: 54606562 | G12: =F12-E12 -> 19882208 | H12: =D12-'MC Calibration'!$C$59*G12 -> 29503259 | I12: =D12+'MC Calibration'!$C$59*G12 -> 58717741 | J12: =IF(D12=0,"",B12/D12) -> 0.64791036
A13: 46266 | B13: 20480550 | C13: 22163100 | D13: 42939900 | E13: 33829170 | F13: 54049012 | G13: =F13-E13 -> 20219842 | H13: =D13-'MC Calibration'!$C$59*G13 -> 28084602 | I13: =D13+'MC Calibration'!$C$59*G13 -> 57795198 | J13: =IF(D13=0,"",B13/D13) -> 0.47695849
A14: 46296 | B14: 23191800 | C14: 29705775 | D14: 53313900 | E14: 42231008 | F14: 65105280 | G14: =F14-E14 -> 22874272 | H14: =D14-'MC Calibration'!$C$59*G14 -> 36508422 | I14: =D14+'MC Calibration'!$C$59*G14 -> 70119378 | J14: =IF(D14=0,"",B14/D14) -> 0.43500475
A15: 46327 | B15: 13112850 | C15: 34921650 | D15: 48703312 | E15: 37542638 | F15: 60936930 | G15: =F15-E15 -> 23394292 | H15: =D15-'MC Calibration'!$C$59*G15 -> 31515781 | I15: =D15+'MC Calibration'!$C$59*G15 -> 65890844 | J15: =IF(D15=0,"",B15/D15) -> 0.26923939
A16: 46357 | B16: 6361875 | C16: 42880875 | D16: 49548375 | E16: 37257142 | F16: 62391518 | G16: =F16-E16 -> 25134375 | H16: =D16-'MC Calibration'!$C$59*G16 -> 31082424 | I16: =D16+'MC Calibration'!$C$59*G16 -> 68014326 | J16: =IF(D16=0,"",B16/D16) -> 0.12839725
A18: Already booked and not yet booked are medians of two separate simulations, so they do not sum exactly to the expected total, which is the median of the combined draw. Medians are not additive.

Sheet MC Calibration
A1: Interval calibration
A4: cutoff | B4: month | C4: actual ($) | D4: P10 | E4: P50 | F4: P90 | G4: spread (P90-P10) | H4: score | I4: inside raw 80% | J4: calibrated low | K4: calibrated high | L4: inside calibrated
A5: 45566 | B5: 45597 | C5: 24372750 | D5: 17841652 | E5: 23064938 | F5: 28510792 | G5: =F5-D5 -> 10669140 | H5: =IF(G5=0,"",ABS(C5-E5)/G5) -> 0.122579 | I5: =IF(AND(C5>=D5,C5<=F5),1,0) -> 1 | J5: =E5-$C$59*G5 -> 15226437 | K5: =E5+$C$59*G5 -> 30903438 | L5: =IF(AND(C5>=J5,C5<=K5),1,0) -> 1
A6: 45566 | B6: 45627 | C6: 62948700 | D6: 40651725 | E6: 48180038 | F6: 57033450 | G6: =F6-D6 -> 16381725 | H6: =IF(G6=0,"",ABS(C6-E6)/G6) -> 0.90153281 | I6: =IF(AND(C6>=D6,C6<=F6),1,0) -> 0 | J6: =E6-$C$59*G6 -> 36144563 | K6: =E6+$C$59*G6 -> 60215512 | L6: =IF(AND(C6>=J6,C6<=K6),1,0) -> 0
A7: 45566 | B7: 45658 | C7: 47153175 | D7: 33080992 | E7: 41310038 | F7: 49993155 | G7: =F7-D7 -> 16912162 | H7: =IF(G7=0,"",ABS(C7-E7)/G7) -> 0.34549913 | I7: =IF(AND(C7>=D7,C7<=F7),1,0) -> 1 | J7: =E7-$C$59*G7 -> 28884856 | K7: =E7+$C$59*G7 -> 53735219 | L7: =IF(AND(C7>=J7,C7<=K7),1,0) -> 1
A8: 45566 | B8: 45689 | C8: 27409275 | D8: 29333145 | E8: 37101600 | F8: 45552188 | G8: =F8-D8 -> 16219042 | H8: =IF(G8=0,"",ABS(C8-E8)/G8) -> 0.59758922 | I8: =IF(AND(C8>=D8,C8<=F8),1,0) -> 0 | J8: =E8-$C$59*G8 -> 25185646 | K8: =E8+$C$59*G8 -> 49017554 | L8: =IF(AND(C8>=J8,C8<=K8),1,0) -> 1
A9: 45566 | B9: 45717 | C9: 33574650 | D9: 28934055 | E9: 37067288 | F9: 45076260 | G9: =F9-D9 -> 16142205 | H9: =IF(G9=0,"",ABS(C9-E9)/G9) -> 0.21636682 | I9: =IF(AND(C9>=D9,C9<=F9),1,0) -> 1 | J9: =E9-$C$59*G9 -> 25207786 | K9: =E9+$C$59*G9 -> 48926789 | L9: =IF(AND(C9>=J9,C9<=K9),1,0) -> 1
A10: 45566 | B10: 45748 | C10: 38260575 | D10: 28441185 | E10: 36378862 | F10: 44067472 | G10: =F10-D10 -> 15626288 | H10: =IF(G10=0,"",ABS(C10-E10)/G10) -> 0.12041968 | I10: =IF(AND(C10>=D10,C10<=F10),1,0) -> 1 | J10: =E10-$C$59*G10 -> 24898400 | K10: =E10+$C$59*G10 -> 47859325 | L10: =IF(AND(C10>=J10,C10<=K10),1,0) -> 1
A11: 45597 | B11: 45627 | C11: 62948700 | D11: 37727775 | E11: 45966638 | F11: 53973705 | G11: =F11-D11 -> 16245930 | H11: =IF(G11=0,"",ABS(C11-E11)/G11) -> 1.0453118 | I11: =IF(AND(C11>=D11,C11<=F11),1,0) -> 0 | J11: =E11-$C$59*G11 -> 34030930 | K11: =E11+$C$59*G11 -> 57902345 | L11: =IF(AND(C11>=J11,C11<=K11),1,0) -> 0
A12: 45597 | B12: 45658 | C12: 47153175 | D12: 31633808 | E12: 39948188 | F12: 49189238 | G12: =F12-D12 -> 17555430 | H12: =IF(G12=0,"",ABS(C12-E12)/G12) -> 0.41041362 | I12: =IF(AND(C12>=D12,C12<=F12),1,0) -> 1 | J12: =E12-$C$59*G12 -> 27050405 | K12: =E12+$C$59*G12 -> 52845970 | L12: =IF(AND(C12>=J12,C12<=K12),1,0) -> 1
A13: 45597 | B13: 45689 | C13: 27409275 | D13: 28689848 | E13: 36095850 | F13: 44978940 | G13: =F13-D13 -> 16289092 | H13: =IF(G13=0,"",ABS(C13-E13)/G13) -> 0.53327556 | I13: =IF(AND(C13>=D13,C13<=F13),1,0) -> 0 | J13: =E13-$C$59*G13 -> 24128431 | K13: =E13+$C$59*G13 -> 48063269 | L13: =IF(AND(C13>=J13,C13<=K13),1,0) -> 1
A14: 45597 | B14: 45717 | C14: 33574650 | D14: 29031158 | E14: 35989050 | F14: 44127112 | G14: =F14-D14 -> 15095955 | H14: =IF(G14=0,"",ABS(C14-E14)/G14) -> 0.15993688 | I14: =IF(AND(C14>=D14,C14<=F14),1,0) -> 1 | J14: =E14-$C$59*G14 -> 24898217 | K14: =E14+$C$59*G14 -> 47079883 | L14: =IF(AND(C14>=J14,C14<=K14),1,0) -> 1
A15: 45597 | B15: 45748 | C15: 40594950 | D15: 29853772 | E15: 37588125 | F15: 45933922 | G15: =F15-D15 -> 16080150 | H15: =IF(G15=0,"",ABS(C15-E15)/G15) -> 0.18698986 | I15: =IF(AND(C15>=D15,C15<=F15),1,0) -> 1 | J15: =E15-$C$59*G15 -> 25774214 | K15: =E15+$C$59*G15 -> 49402036 | L15: =IF(AND(C15>=J15,C15<=K15),1,0) -> 1
A16: 45597 | B16: 45778 | C16: 43752900 | D16: 28549785 | E16: 36192000 | F16: 44753002 | G16: =F16-D16 -> 16203218 | H16: =IF(G16=0,"",ABS(C16-E16)/G16) -> 0.46662954 | I16: =IF(AND(C16>=D16,C16<=F16),1,0) -> 1 | J16: =E16-$C$59*G16 -> 24287673 | K16: =E16+$C$59*G16 -> 48096327 | L16: =IF(AND(C16>=J16,C16<=K16),1,0) -> 1
... A52: 45778 | B52: 45962 | C52: 29260125 | D52: 25649332 | E52: 33013650 | F52: 41257185 | G52: =F52-D52 -> 15607852 | H52: =IF(G52=0,"",ABS(C52-E52)/G52) -> 0.24048952 | I52: =IF(AND(C52>=D52,C52<=F52),1,0) -> 1 | J52: =E52-$C$59*G52 -> 21546731 | K52: =E52+$C$59*G52 -> 44480569 | L52: =IF(AND(C52>=J52,C52<=K52),1,0) -> 1
A54: Conformal calibration
A55: Split conformal. Rank the scores, take the one at the 80th position by count, and use it as the multiplier on the spread. No distributional assumption; it measures what the model actually did against outcomes.
A57: observations (n) | C57: =COUNT(H5:H52) -> 48
A58: rank used = ROUNDUP((n+1) x 0.80, 0) | C58: =MIN(ROUNDUP((C57+1)*0.8,0),C57) -> 40
A59: q80 = that ranked score | C59: =SMALL(H5:H52,C58) -> 0.73468909
A60: stated coverage | C60: =0.8 -> 0.8
A61: raw coverage | C61: =AVERAGE(I5:I52) -> 0.625
A62: calibrated coverage | C62: =AVERAGE(L5:L52) -> 0.83333333
A63: widening factor = 2 x q80 | C63: =2*C59 -> 1.4693782
